Workbook

Sheet alpaca
A1: Language | B1: prompt | C1: Program Name | D1: C1 - Classes and Interfaces | H1: C2_Constructor | L1: C2a_Constructor_Parameters | P1: C3 - Attributes and Types | T1: C3a-Visibility attributes | X1: C4 - Methods | AB1: C4a-Parameters | AF1: C4b-Visibility methods_Constructors | AJ1: C5 - Inheritance Relationship | AN1: C6 - Realization Relationship | AR1: C7 - Association Relationship | AV1: C8 - Aggregation/Composition Relationship | AZ1: C9- Direction | BD1: C10 - Abstract Classes and Methods | BH1: C11 - Static Classes and Methods | BL1: C12 - Association Multiplicity | BP1: C13 - Dependency Relationship | BT1: TP | BU1: FN | BV1: FP | BW1: Recall | BX1: Precision | BY1: F1 | CC1: Program Name | CD1: =BW1 -> Recall | CE1: =BX1 -> Precision | CF1: =BY1 -> F1
D2: GT | E2: TP | F2: FN | G2: FP | H2: GT | I2: TP | J2: FN | K2: FP | L2: GT | M2: TP | N2: FN | O2: FP | P2: GT | Q2: TP | R2: FN | S2: FP | T2: GT | U2: TP | V2: FN | W2: FP | X2: GT | Y2: TP | Z2: FN | AA2: FP | AB2: GT | AC2: TP | AD2: FN | AE2: FP | AF2: GT | AG2: TP | AH2: FN | AI2: FP | AJ2: GT | AK2: TP | AL2: FN | AM2: FP | AN2: GT | AO2: TP | AP2: FN | AQ2: FP | AR2: GT | AS2: TP | AT2: FN | AU2: FP | AV2: GT | AW2: TP | AX2: FN | AY2: FP | AZ2: GT | BA2: TP | BB2: FN | BC2: FP | BD2: GT | BE2: TP | BF2: FN | BG2: FP | BH2: GT | BI2: TP | BJ2: FN | BK2: FP | BL2: GT | BM2: TP | BN2: FN | BO2: FP | BP2: GT | BQ2: TP | BR2: FN | BS2: FP
A3: python | B3: """Below is an instruction that describes a task, paired with an input that provides further context. Write a response, which is in JSON format that appropriately solves the following Task: ### Instruction: Generate a concise UML class diagram for the provided Python code. The output should: 1. Define each class and interface only once, including its attributes, methods, and relationships. 2. Include all relationships (Inheritance, Realization, Dependency, Association, Composition, Aggregation) without duplication. 3. Avoid redundant or repeated operations, classes, or relationships. ### Input: {code_content} ### Response: """ | C3: ex1_1 | D3: 3 | E3: 3 | F3: =D3-E3 -> 0 | G3: 0 | H3: 3 | I3: 0 | J3: =H3-I3 -> 3 | K3: 0 | L3: 6 | M3: 0 | N3: =L3-M3 -> 6 | O3: 0 | P3: 4 | Q3: 4 | R3: =P3-Q3 -> 0 | S3: 0 | T3: 4 | U3: 4 | V3: =T3-U3 -> 0 | W3: 0 | X3: 3 | Y3: 3 | Z3: =X3-Y3 -> 0 | AA3: 0 | AB3: 0 | AC3: 0 | AD3: =AB3-AC3 -> 0 | AE3: 0 | AF3: 3 | AG3: 3 | AH3: =AF3-AG3 -> 0 | AI3: 0 | AJ3: 2 | AK3: 2 | AL3: =AJ3-AK3 -> 0 | AM3: 0 | AN3: 0 | AO3: 0 | AP3: =AN3-AO3 -> 0 | AQ3: 0 | AR3: 0 | AS3: 0 | AT3: =AR3-AS3 -> 0 | AU3: 2 | AV3: 0 | AW3: 0 | AX3: =AV3-AW3 -> 0 | AY3: 0 | AZ3: 2 | BA3: 2 | BB3: =AZ3-BA3 -> 0 | BC3: 0 | BD3: 0 | BE3: 0 | BF3: =BD3-BE3 -> 0 | BG3: 0 | BH3: 0 | BI3: 0 | BJ3: =BH3-BI3 -> 0 | BK3: 0 | BL3: 0 | BM3: 0 | BN3: =BL3-BM3 -> 0 | BO3: 0 | BP3: 0 | BQ3: 0 | BR3: =BP3-BQ3 -> 0 | BS3: 0 | BT3: =SUM(E3,I3,M3,Q3,U3,Y3,AC3,AG3,AK3,AO3,AS3,AW3,BE3,BI3,BM3,BQ3,BA3) -> 21 | BU3: =SUM(BR3,BN3,BJ3,BF3,AX3,AT3,AP3,AL3,AH3,AD3,Z3,V3,R3,N3,J3,F3,BB3) -> 9 | BV3: =SUM(BS3,BO3,BK3,BG3,AY3,AU3,AQ3,AM3,AI3,AE3,AA3,W3,S3,O3,K3,G3, BC3) -> 2 | BW3: =BT3/(BT3+BU3) -> 0.7 | BX3: =BT3/(BT3+BV3) -> 0.91304348 | BY3: =2*(BX3*BW3)/(BX3+BW3) -> 0.79245283 | CC3: ex1 | CD3: =AVERAGE(BW3:BW4) -> 0.7 | CE3: =AVERAGE(BX3:BX4) -> 0.95652174 | CF3: =AVERAGE(BY3:BY4) -> 0.80799112
A4: python | C4: ex1_2 | D4: 3 | E4: 3 | F4: =D4-E4 -> 0 | G4: 0 | H4: 3 | I4: 0 | J4: =H4-I4 -> 3 | K4: 0 | L4: 6 | M4: 0 | N4: =L4-M4 -> 6 | O4: 0 | P4: 4 | Q4: 4 | R4: =P4-Q4 -> 0 | S4: 0 | T4: 4 | U4: 4 | V4: =T4-U4 -> 0 | W4: 0 | X4: 3 | Y4: 3 | Z4: =X4-Y4 -> 0 | AA4: 0 | AB4: 0 | AC4: 0 | AD4: =AB4-AC4 -> 0 | AE4: 0 | AF4: 3 | AG4: 3 | AH4: =AF4-AG4 -> 0 | AI4: 0 | AJ4: 2 | AK4: 2 | AL4: =AJ4-AK4 -> 0 | AM4: 0 | AN4: 0 | AO4: 0 | AP4: =AN4-AO4 -> 0 | AQ4: 0 | AR4: 0 | AS4: 0 | AT4: =AR4-AS4 -> 0 | AU4: 0 | AV4: 0 | AW4: 0 | AX4: =AV4-AW4 -> 0 | AY4: 0 | AZ4: 2 | BA4: 2 | BB4: =AZ4-BA4 -> 0 | BC4: 0 | BD4: 0 | BE4: 0 | BF4: =BD4-BE4 -> 0 | BG4: 0 | BH4: 0 | BI4: 0 | BJ4: =BH4-BI4 -> 0 | BK4: 0 | BL4: 0 | BM4: 0 | BN4: =BL4-BM4 -> 0 | BO4: 0 | BP4: 0 | BQ4: 0 | BR4: =BP4-BQ4 -> 0 | BS4: 0 | BT4: =SUM(E4,I4,M4,Q4,U4,Y4,AC4,AG4,AK4,AO4,AS4,AW4,BE4,BI4,BM4,BQ4,BA4) -> 21 | BU4: =SUM(BR4,BN4,BJ4,BF4,AX4,AT4,AP4,AL4,AH4,AD4,Z4,V4,R4,N4,J4,F4,BB4) -> 9 | BV4: =SUM(BS4,BO4,BK4,BG4,AY4,AU4,AQ4,AM4,AI4,AE4,AA4,W4,S4,O4,K4,G4, BC4) -> 0 | BW4: =BT4/(BT4+BU4) -> 0.7 | BX4: =BT4/(BT4+BV4) -> 1 | BY4: =2*(BX4*BW4)/(BX4+BW4) -> 0.82352941 | CC4: ex2 | CD4: =AVERAGE(BW5:BW6) -> 0.8 | CE4: =AVERAGE(BX5:BX6) -> 0.61538462 | CF4: =AVERAGE(BY5:BY6) -> 0.69565217
A5: python | C5: ex2_1 | D5: 2 | E5: 2 | F5: =D5-E5 -> 0 | G5: 0 | H5: 2 | I5: 2 | J5: =H5-I5 -> 0 | K5: 0 | L5: 0 | M5: 0 | N5: =L5-M5 -> 0 | O5: 0 | P5: 0 | Q5: 0 | R5: =P5-Q5 -> 0 | S5: 2 | T5: 0 | U5: 0 | V5: =T5-U5 -> 0 | W5: 0 | X5: 2 | Y5: 2 | Z5: =X5-Y5 -> 0 | AA5: 0 | AB5: 0 | AC5: 0 | AD5: =AB5-AC5 -> 0 | AE5: 0 | AF5: 2 | AG5: 2 | AH5: =AF5-AG5 -> 0 | AI5: 0 | AJ5: 0 | AK5: 0 | AL5: =AJ5-AK5 -> 0 | AM5: 0 | AN5: 0 | AO5: 0 | AP5: =AN5-AO5 -> 0 | AQ5: 0 | AR5: 0 | AS5: 0 | AT5: =AR5-AS5 -> 0 | AU5: 0 | AV5: 1 | AW5: 0 | AX5: =AV5-AW5 -> 1 | AY5: 1 | AZ5: 1 | BA5: 0 | BB5: =AZ5-BA5 -> 1 | BC5: 1 | BD5: 0 | BE5: 0 | BF5: =BD5-BE5 -> 0 | BG5: 0 | BH5: 0 | BI5: 0 | BJ5: =BH5-BI5 -> 0 | BK5: 0 | BL5: 0 | BM5: 0 | BN5: =BL5-BM5 -> 0 | BO5: 1 | BP5: 0 | BQ5: 0 | BR5: =BP5-BQ5 -> 0 | BS5: 0 | BT5: =SUM(E5,I5,M5,Q5,U5,Y5,AC5,AG5,AK5,AO5,AS5,AW5,BE5,BI5,BM5,BQ5,BA5) -> 8 | BU5: =SUM(BR5,BN5,BJ5,BF5,AX5,AT5,AP5,AL5,AH5,AD5,Z5,V5,R5,N5,J5,F5,BB5) -> 2 | BV5: =SUM(BS5,BO5,BK5,BG5,AY5,AU5,AQ5,AM5,AI5,AE5,AA5,W5,S5,O5,K5,G5, BC5) -> 5 | BW5: =BT5/(BT5+BU5) -> 0.8 | BX5: =BT5/(BT5+BV5) -> 0.61538462 | BY5: =2*(BX5*BW5)/(BX5+BW5) -> 0.69565217 | CC5: ex3 | CD5: =AVERAGE(BW7:BW8) -> 0.71875 | CE5: =AVERAGE(BX7:BX8) -> 0.88461538 | CF5: =AVERAGE(BY7:BY8) -> 0.79310345
A6: python | C6: ex2_2 | D6: 2 | E6: 2 | F6: =D6-E6 -> 0 | G6: 0 | H6: 2 | I6: 2 | J6: =H6-I6 -> 0 | K6: 0 | L6: 0 | M6: 0 | N6: =L6-M6 -> 0 | O6: 0 | P6: 0 | Q6: 0 | R6: =P6-Q6 -> 0 | S6: 2 | T6: 0 | U6: 0 | V6: =T6-U6 -> 0 | W6: 0 | X6: 2 | Y6: 2 | Z6: =X6-Y6 -> 0 | AA6: 0 | AB6: 0 | AC6: 0 | AD6: =AB6-AC6 -> 0 | AE6: 0 | AF6: 2 | AG6: 2 | AH6: =AF6-AG6 -> 0 | AI6: 0 | AJ6: 0 | AK6: 0 | AL6: =AJ6-AK6 -> 0 | AM6: 0 | AN6: 0 | AO6: 0 | AP6: =AN6-AO6 -> 0 | AQ6: 0 | AR6: 0 | AS6: 0 | AT6: =AR6-AS6 -> 0 | AU6: 0 | AV6: 1 | AW6: 0 | AX6: =AV6-AW6 -> 1 | AY6: 1 | AZ6: 1 | BA6: 0 | BB6: =AZ6-BA6 -> 1 | BC6: 1 | BD6: 0 | BE6: 0 | BF6: =BD6-BE6 -> 0 | BG6: 0 | BH6: 0 | BI6: 0 | BJ6: =BH6-BI6 -> 0 | BK6: 0 | BL6: 0 | BM6: 0 | BN6: =BL6-BM6 -> 0 | BO6: 1 | BP6: 0 | BQ6: 0 | BR6: =BP6-BQ6 -> 0 | BS6: 0 | BT6: =SUM(E6,I6,M6,Q6,U6,Y6,AC6,AG6,AK6,AO6,AS6,AW6,BE6,BI6,BM6,BQ6,BA6) -> 8 | BU6: =SUM(BR6,BN6,BJ6,BF6,AX6,AT6,AP6,AL6,AH6,AD6,Z6,V6,R6,N6,J6,F6,BB6) -> 2 | BV6: =SUM(BS6,BO6,BK6,BG6,AY6,AU6,AQ6,AM6,AI6,AE6,AA6,W6,S6,O6,K6,G6, BC6) -> 5 | BW6: =BT6/(BT6+BU6) -> 0.8 | BX6: =BT6/(BT6+BV6) -> 0.61538462 | BY6: =2*(BX6*BW6)/(BX6+BW6) -> 0.69565217 | CC6: ex4 | CD6: =AVERAGE(BW9:BW10) -> 0.95833333 | CE6: =AVERAGE(BX9:BX10) -> 0.89285714 | CF6: =AVERAGE(BY9:BY10) -> 0.92307692
A7: python | C7: ex3_1 | D7: 2 | E7: 2 | F7: =D7-E7 -> 0 | G7: 0 | H7: 1 | I7: 0 | J7: =H7-I7 -> 1 | K7: 0 | L7: 1 | M7: 0 | N7: =L7-M7 -> 1 | O7: 0 | P7: 1 | Q7: 1 | R7: =P7-Q7 -> 0 | S7: 0 | T7: 1 | U7: 1 | V7: =T7-U7 -> 0 | W7: 0 | X7: 3 | Y7: 3 | Z7: =X7-Y7 -> 0 | AA7: 1 | AB7: 0 | AC7: 0 | AD7: =AB7-AC7 -> 0 | AE7: 0 | AF7: 3 | AG7: 3 | AH7: =AF7-AG7 -> 0 | AI7: 0 | AJ7: 0 | AK7: 0 | AL7: =AJ7-AK7 -> 0 | AM7: 1 | AN7: 1 | AO7: 0 | AP7: =AN7-AO7 -> 1 | AQ7: 0 | AR7: 0 | AS7: 0 | AT7: =AR7-AS7 -> 0 | AU7: 0 | AV7: 0 | AW7: 0 | AX7: =AV7-AW7 -> 0 | AY7: 0 | AZ7: 1 | BA7: 1 | BB7: =AZ7-BA7 -> 0 | BC7: 0 | BD7: 2 | BE7: 0 | BF7: =BD7-BE7 -> 2 | BG7: 0 | BH7: 0 | BI7: 0 | BJ7: =BH7-BI7 -> 0 | BK7: 0 | BL7: 0 | BM7: 0 | BN7: =BL7-BM7 -> 0 | BO7: 0 | BP7: 0 | BQ7: 0 | BR7: =BP7-BQ7 -> 0 | BS7: 0 | BT7: =SUM(E7,I7,M7,Q7,U7,Y7,AC7,AG7,AK7,AO7,AS7,AW7,BE7,BI7,BM7,BQ7,BA7) -> 11 | BU7: =SUM(BR7,BN7,BJ7,BF7,AX7,AT7,AP7,AL7,AH7,AD7,Z7,V7,R7,N7,J7,F7,BB7) -> 5 | BV7: =SUM(BS7,BO7,BK7,BG7,AY7,AU7,AQ7,AM7,AI7,AE7,AA7,W7,S7,O7,K7,G7, BC7) -> 2 | BW7: =BT7/(BT7+BU7) -> 0.6875 | BX7: =BT7/(BT7+BV7) -> 0.84615385 | BY7: =2*(BX7*BW7)/(BX7+BW7) -> 0.75862069 | CC7: ex5 | CD7: =AVERAGE(BW11:BW12) -> 0.73809524 | CE7: =AVERAGE(BX11:BX12) -> 0.8377193 | CF7: =AVERAGE(BY11:BY12) -> 0.78461538
A8: python | C8: ex3_2 | D8: 2 | E8: 2 | F8: =D8-E8 -> 0 | G8: 0 | H8: 1 | I8: 0 | J8: =H8-I8 -> 1 | K8: 0 | L8: 1 | M8: 0 | N8: =L8-M8 -> 1 | O8: 0 | P8: 1 | Q8: 1 | R8: =P8-Q8 -> 0 | S8: 0 | T8: 1 | U8: 1 | V8: =T8-U8 -> 0 | W8: 0 | X8: 3 | Y8: 3 | Z8: =X8-Y8 -> 0 | AA8: 0 | AB8: 0 | AC8: 0 | AD8: =AB8-AC8 -> 0 | AE8: 0 | AF8: 3 | AG8: 3 | AH8: =AF8-AG8 -> 0 | AI8: 0 | AJ8: 0 | AK8: 0 | AL8: =AJ8-AK8 -> 0 | AM8: 1 | AN8: 1 | AO8: 0 | AP8: =AN8-AO8 -> 1 | AQ8: 0 | AR8: 0 | AS8: 0 | AT8: =AR8-AS8 -> 0 | AU8: 0 | AV8: 0 | AW8: 0 | AX8: =AV8-AW8 -> 0 | AY8: 0 | AZ8: 1 | BA8: 1 | BB8: =AZ8-BA8 -> 0 | BC8: 0 | BD8: 2 | BE8: 1 | BF8: =BD8-BE8 -> 1 | BG8: 0 | BH8: 0 | BI8: 0 | BJ8: =BH8-BI8 -> 0 | BK8: 0 | BL8: 0 | BM8: 0 | BN8: =BL8-BM8 -> 0 | BO8: 0 | BP8: 0 | BQ8: 0 | BR8: =BP8-BQ8 -> 0 | BS8: 0 | BT8: =SUM(E8,I8,M8,Q8,U8,Y8,AC8,AG8,AK8,AO8,AS8,AW8,BE8,BI8,BM8,BQ8,BA8) -> 12 | BU8: =SUM(BR8,BN8,BJ8,BF8,AX8,AT8,AP8,AL8,AH8,AD8,Z8,V8,R8,N8,J8,F8,BB8) -> 4 | BV8: =SUM(BS8,BO8,BK8,BG8,AY8,AU8,AQ8,AM8,AI8,AE8,AA8,W8,S8,O8,K8,G8, BC8) -> 1 | BW8: =BT8/(BT8+BU8) -> 0.75 | BX8: =BT8/(BT8+BV8) -> 0.92307692 | BY8: =2*(BX8*BW8)/(BX8+BW8) -> 0.82758621 | CC8: ex6 | CD8: =AVERAGE(BW13:BW14) -> 0.83333333 | CE8: =AVERAGE(BX13:BX14) -> 1 | CF8: =AVERAGE(BY13:BY14) -> 0.9
A9: python | C9: ex4_1 | D9: 1 | E9: 1 | F9: =D9-E9 -> 0 | G9: 0 | H9: 0 | I9: 0 | J9: =H9-I9 -> 0 | K9: 0 | L9: 0 | M9: 0 | N9: =L9-M9 -> 0 | O9: 0 | P9: 0 | Q9: 0 | R9: =P9-Q9 -> 0 | S9: 0 | T9: 0 | U9: 0 | V9: =T9-U9 -> 0 | W9: 0 | X9: 3 | Y9: 3 | Z9: =X9-Y9 -> 0 | AA9: 0 | AB9: 4 | AC9: 4 | AD9: =AB9-AC9 -> 0 | AE9: 0 | AF9: 3 | AG9: 3 | AH9: =AF9-AG9 -> 0 | AI9: 0 | AJ9: 0 | AK9: 0 | AL9: =AJ9-AK9 -> 0 | AM9: 0 | AN9: 0 | AO9: 0 | AP9: =AN9-AO9 -> 0 | AQ9: 0 | AR9: 0 | AS9: 0 | AT9: =AR9-AS9 -> 0 | AU9: 0 | AV9: 0 | AW9: 0 | AX9: =AV9-AW9 -> 0 | AY9: 1 | AZ9: 0 | BA9: 0 | BB9: =AZ9-BA9 -> 0 | BC9: 1 | BD9: 0 | BE9: 0 | BF9: =BD9-BE9 -> 0 | BG9: 0 | BH9: 1 | BI9: 0 | BJ9: =BH9-BI9 -> 1 | BK9: 0 | BL9: 0 | BM9: 0 | BN9: =BL9-BM9 -> 0 | BO9: 1 | BP9: 0 | BQ9: 0 | BR9: =BP9-BQ9 -> 0 | BS9: 0 | BT9: =SUM(E9,I9,M9,Q9,U9,Y9,AC9,AG9,AK9,AO9,AS9,AW9,BE9,BI9,BM9,BQ9,BA9) -> 11 | BU9: =SUM(BR9,BN9,BJ9,BF9,AX9,AT9,AP9,AL9,AH9,AD9,Z9,V9,R9,N9,J9,F9,BB9) -> 1 | BV9: =SUM(BS9,BO9,BK9,BG9,AY9,AU9,AQ9,AM9,AI9,AE9,AA9,W9,S9,O9,K9,G9, BC9) -> 3 | BW9: =BT9/(BT9+BU9) -> 0.91666667 | BX9: =BT9/(BT9+BV9) -> 0.78571429 | BY9: =2*(BX9*BW9)/(BX9+BW9) -> 0.84615385 | CC9: ex7 | CD9: =AVERAGE(BW15:BW16) -> 1 | CE9: =AVERAGE(BX15:BX16) -> 1 | CF9: =AVERAGE(BY15:BY16) -> 1
A10: python | C10: ex4_2 | D10: 1 | E10: 1 | F10: =D10-E10 -> 0 | G10: 0 | H10: 0 | I10: 0 | J10: =H10-I10 -> 0 | K10: 0 | L10: 0 | M10: 0 | N10: =L10-M10 -> 0 | O10: 0 | P10: 0 | Q10: 0 | R10: =P10-Q10 -> 0 | S10: 0 | T10: 0 | U10: 0 | V10: =T10-U10 -> 0 | W10: 0 | X10: 3 | Y10: 3 | Z10: =X10-Y10 -> 0 | AA10: 0 | AB10: 4 | AC10: 4 | AD10: =AB10-AC10 -> 0 | AE10: 0 | AF10: 3 | AG10: 3 | AH10: =AF10-AG10 -> 0 | AI10: 0 | AJ10: 0 | AK10: 0 | AL10: =AJ10-AK10 -> 0 | AM10: 0 | AN10: 0 | AO10: 0 | AP10: =AN10-AO10 -> 0 | AQ10: 0 | AR10: 0 | AS10: 0 | AT10: =AR10-AS10 -> 0 | AU10: 0 | AV10: 0 | AW10: 0 | AX10: =AV10-AW10 -> 0 | AY10: 0 | AZ10: 0 | BA10: 0 | BB10: =AZ10-BA10 -> 0 | BC10: 0 | BD10: 0 | BE10: 0 | BF10: =BD10-BE10 -> 0 | BG10: 0 | BH10: 1 | BI10: 1 | BJ10: =BH10-BI10 -> 0 | BK10: 0 | BL10: 0 | BM10: 0 | BN10: =BL10-BM10 -> 0 | BO10: 0 | BP10: 0 | BQ10: 0 | BR10: =BP10-BQ10 -> 0 | BS10: 0 | BT10: =SUM(E10,I10,M10,Q10,U10,Y10,AC10,AG10,AK10,AO10,AS10,AW10,BE10,BI10,BM10,BQ10,BA10) -> 12 | BU10: =SUM(BR10,BN10,BJ10,BF10,AX10,AT10,AP10,AL10,AH10,AD10,Z10,V10,R10,N10,J10,F10,BB10) -> 0 | BV10: =SUM(BS10,BO10,BK10,BG10,AY10,AU10,AQ10,AM10,AI10,AE10,AA10,W10,S10,O10,K10,G10, BC10) -> 0 | BW10: =BT10/(BT10+BU10) -> 1 | BX10: =BT10/(BT10+BV10) -> 1 | BY10: =2*(BX10*BW10)/(BX10+BW10) -> 1 | CC10: ex8 | CD10: =AVERAGE(BW17:BW18) -> 0.86363636 | CE10: =AVERAGE(BX17:BX18) -> 0.79166667 | CF10: =AVERAGE(BY17:BY18) -> 0.82608696
A11: python | C11: ex5_1 | D11: 2 | E11: 2 | F11: =D11-E11 -> 0 | G11: 0 | H11: 1 | I11: 0 | J11: =H11-I11 -> 1 | K11: 0 | L11: 2 | M11: 0 | N11: =L11-M11 -> 2 | O11: 0 | P11: 2 | Q11: 2 | R11: =P11-Q11 -> 0 | S11: 2 | T11: 2 | U11: 2 | V11: =T11-U11 -> 0 | W11: 0 | X11: 4 | Y11: 4 | Z11: =X11-Y11 -> 0 | AA11: 1 | AB11: 0 | AC11: 0 | AD11: =AB11-AC11 -> 0 | AE11: 0 | AF11: 4 | AG11: 4 | AH11: =AF11-AG11 -> 0 | AI11: 0 | AJ11: 1 | AK11: 1 | AL11: =AJ11-AK11 -> 0 | AM11: 0 | AN11: 0 | AO11: 0 | AP11: =AN11-AO11 -> 0 | AQ11: 0 | AR11: 0 | AS11: 0 | AT11: =AR11-AS11 -> 0 | AU11: 0 | AV11: 0 | AW11: 0 | AX11: =AV11-AW11 -> 0 | AY11: 0 | AZ11: 1 | BA11: 0 | BB11: =AZ11-BA11 -> 1 | BC11: 0 | BD11: 2 | BE11: 0 | BF11: =BD11-BE11 -> 2 | BG11: 0 | BH11: 0 | BI11: 0 | BJ11: =BH11-BI11 -> 0 | BK11: 0 | BL11: 0 | BM11: 0 | BN11: =BL11-BM11 -> 0 | BO11: 0 | BP11: 0 | BQ11: 0 | BR11: =BP11-BQ11 -> 0 | BS11: 0 | BT11: =SUM(E11,I11,M11,Q11,U11,Y11,AC11,AG11,AK11,AO11,AS11,AW11,BE11,BI11,BM11,BQ11,BA11) -> 15 | BU11: =SUM(BR11,BN11,BJ11,BF11,AX11,AT11,AP11,AL11,AH11,AD11,Z11,V11,R11,N11,J11,F11,BB11) -> 6 | BV11: =SUM(BS11,BO11,BK11,BG11,AY11,AU11,AQ11,AM11,AI11,AE11,AA11,W11,S11,O11,K11,G11, BC11) -> 3 | BW11: =BT11/(BT11+BU11) -> 0.71428571 | BX11: =BT11/(BT11+BV11) -> 0.83333333 | BY11: =2*(BX11*BW11)/(BX11+BW11) -> 0.76923077 | CC11: ex9 | CD11: =AVERAGE(BW19:BW20) -> 0.79166667 | CE11: =AVERAGE(BX19:BX20) -> 0.70054945 | CF11: =AVERAGE(BY19:BY20) -> 0.74307692
A12: python | C12: ex5_2 | D12: 2 | E12: 2 | F12: =D12-E12 -> 0 | G12: 0 | H12: 1 | I12: 0 | J12: =H12-I12 -> 1 | K12: 0 | L12: 2 | M12: 0 | N12: =L12-M12 -> 2 | O12: 0 | P12: 2 | Q12: 2 | R12: =P12-Q12 -> 0 | S12: 2 | T12: 2 | U12: 2 | V12: =T12-U12 -> 0 | W12: 0 | X12: 4 | Y12: 4 | Z12: =X12-Y12 -> 0 | AA12: 1 | AB12: 0 | AC12: 0 | AD12: =AB12-AC12 -> 0 | AE12: 0 | AF12: 4 | AG12: 4 | AH12: =AF12-AG12 -> 0 | AI12: 0 | AJ12: 1 | AK12: 1 | AL12: =AJ12-AK12 -> 0 | AM12: 0 | AN12: 0 | AO12: 0 | AP12: =AN12-AO12 -> 0 | AQ12: 0 | AR12: 0 | AS12: 0 | AT12: =AR12-AS12 -> 0 | AU12: 0 | AV12: 0 | AW12: 0 | AX12: =AV12-AW12 -> 0 | AY12: 0 | AZ12: 1 | BA12: 0 | BB12: =AZ12-BA12 -> 1 | BC12: 0 | BD12: 2 | BE12: 1 | BF12: =BD12-BE12 -> 1 | BG12: 0 | BH12: 0 | BI12: 0 | BJ12: =BH12-BI12 -> 0 | BK12: 0 | BL12: 0 | BM12: 0 | BN12: =BL12-BM12 -> 0 | BO12: 0 | BP12: 0 | BQ12: 0 | BR12: =BP12-BQ12 -> 0 | BS12: 0 | BT12: =SUM(E12,I12,M12,Q12,U12,Y12,AC12,AG12,AK12,AO12,AS12,AW12,BE12,BI12,BM12,BQ12,BA12) -> 16 | BU12: =SUM(BR12,BN12,BJ12,BF12,AX12,AT12,AP12,AL12,AH12,AD12,Z12,V12,R12,N12,J12,F12,BB12) -> 5 | BV12: =SUM(BS12,BO12,BK12,BG12,AY12,AU12,AQ12,AM12,AI12,AE12,AA12,W12,S12,O12,K12,G12, BC12) -> 3 | BW12: =BT12/(BT12+BU12) -> 0.76190476 | BX12: =BT12/(BT12+BV12) -> 0.84210526 | BY12: =2*(BX12*BW12)/(BX12+BW12) -> 0.8 | CC12: ex10 | CD12: =AVERAGE(BW21:BW22) -> 0.58823529 | CE12: =AVERAGE(BX21:BX22) -> 0.76923077 | CF12: =AVERAGE(BY21:BY22) -> 0.66666667
A13: python | C13: ex6_1 | D13: 4 | E13: 4 | F13: =D13-E13 -> 0 | G13: 0 | H13: 0 | I13: 0 | J13: =H13-I13 -> 0 | K13: 0 | L13: 0 | M13: 0 | N13: =L13-M13 -> 0 | O13: 0 | P13: 0 | Q13: 0 | R13: =P13-Q13 -> 0 | S13: 0 | T13: 0 | U13: 0 | V13: =T13-U13 -> 0 | W13: 0 | X13: 4 | Y13: 4 | Z13: =X13-Y13 -> 0 | AA13: 0 | AB13: 0 | AC13: 0 | AD13: =AB13-AC13 -> 0 | AE13: 0 | AF13: 4 | AG13: 4 | AH13: =AF13-AG13 -> 0 | AI13: 0 | AJ13: 3 | AK13: 3 | AL13: =AJ13-AK13 -> 0 | AM13: 0 | AN13: 0 | AO13: 0 | AP13: =AN13-AO13 -> 0 | AQ13: 0 | AR13: 0 | AS13: 0 | AT13: =AR13-AS13 -> 0 | AU13: 0 | AV13: 0 | AW13: 0 | AX13: =AV13-AW13 -> 0 | AY13: 0 | AZ13: 3 | BA13: 3 | BB13: =AZ13-BA13 -> 0 | BC13: 0 | BD13: 0 | BE13: 0 | BF13: =BD13-BE13 -> 0 | BG13: 0 | BH13: 0 | BI13: 0 | BJ13: =BH13-BI13 -> 0 | BK13: 0 | BL13: 0 | BM13: 0 | BN13: =BL13-BM13 -> 0 | BO13: 0 | BP13: 0 | BQ13: 0 | BR13: =BP13-BQ13 -> 0 | BS13: 0 | BT13: =SUM(E13,I13,M13,Q13,U13,Y13,AC13,AG13,AK13,AO13,AS13,AW13,BE13,BI13,BM13,BQ13,BA13) -> 18 | BU13: =SUM(BR13,BN13,BJ13,BF13,AX13,AT13,AP13,AL13,AH13,AD13,Z13,V13,R13,N13,J13,F13,BB13) -> 0 | BV13: =SUM(BS13,BO13,BK13,BG13,AY13,AU13,AQ13,AM13,AI13,AE13,AA13,W13,S13,O13,K13,G13, BC13) -> 0 | BW13: =BT13/(BT13+BU13) -> 1 | BX13: =BT13/(BT13+BV13) -> 1 | BY13: =2*(BX13*BW13)/(BX13+BW13) -> 1 | CC13: ex11 | CD13: =AVERAGE(BW23:BW24) -> 0.81818182 | CE13: =AVERAGE(BX23:BX24) -> 0.75 | CF13: =AVERAGE(BY23:BY24) -> 0.7826087
A14: python | C14: ex6_2 | D14: 4 | E14: 4 | F14: =D14-E14 -> 0 | G14: 0 | H14: 0 | I14: 0 | J14: 0 | K14: 0 | L14: 0 | M14: 0 | N14: 0 | O14: 0 | P14: 0 | Q14: 0 | R14: =P14-Q14 -> 0 | S14: 0 | T14: 0 | U14: 0 | V14: 0 | W14: 0 | X14: 4 | Y14: 4 | Z14: =X14-Y14 -> 0 | AA14: 0 | AB14: 0 | AC14: 0 | AD14: =AB14-AC14 -> 0 | AE14: 0 | AF14: 4 | AG14: 4 | AH14: =AF14-AG14 -> 0 | AI14: 0 | AJ14: 3 | AK14: 0 | AL14: =AJ14-AK14 -> 3 | AM14: 0 | AN14: 0 | AO14: 0 | AP14: =AN14-AO14 -> 0 | AQ14: 0 | AR14: 0 | AS14: 0 | AT14: =AR14-AS14 -> 0 | AU14: 0 | AV14: 0 | AW14: 0 | AX14: =AV14-AW14 -> 0 | AY14: 0 | AZ14: 3 | BA14: 0 | BB14: =AZ14-BA14 -> 3 | BC14: 0 | BD14: 0 | BE14: 0 | BF14: =BD14-BE14 -> 0 | BG14: 0 | BH14: 0 | BI14: 0 | BJ14: =BH14-BI14 -> 0 | BK14: 0 | BL14: 0 | BM14: 0 | BN14: =BL14-BM14 -> 0 | BO14: 0 | BP14: 0 | BQ14: 0 | BR14: =BP14-BQ14 -> 0 | BS14: 0 | BT14: =SUM(E14,I14,M14,Q14,U14,Y14,AC14,AG14,AK14,AO14,AS14,AW14,BE14,BI14,BM14,BQ14,BA14) -> 12 | BU14: =SUM(BR14,BN14,BJ14,BF14,AX14,AT14,AP14,AL14,AH14,AD14,Z14,V14,R14,N14,J14,F14,BB14) -> 6 | BV14: =SUM(BS14,BO14,BK14,BG14,AY14,AU14,AQ14,AM14,AI14,AE14,AA14,W14,S14,O14,K14,G14, BC14) -> 0 | BW14: =BT14/(BT14+BU14) -> 0.66666667 | BX14: =BT14/(BT14+BV14) -> 1 | BY14: =2*(BX14*BW14)/(BX14+BW14) -> 0.8 | CC14: ex12 | CD14: =AVERAGE(BW25:BW26) -> 0.75 | CE14: =AVERAGE(BX25:BX26) -> 0.85714286 | CF14: =AVERAGE(BY25:BY26) -> 0.8
A15: python | C15: ex7_1 | D15: 3 | E15: 3 | F15: =D15-E15 -> 0 | G15: 0 | H15: 0 | I15: 0 | J15: =H15-I15 -> 0 | K15: 0 | L15: 0 | M15: 0 | N15: =L15-M15 -> 0 | O15: 0 | P15: 0 | Q15: 0 | R15: =P15-Q15 -> 0 | S15: 0 | T15: 0 | U15: 0 | V15: =T15-U15 -> 0 | W15: 0 | X15: 3 | Y15: 3 | Z15: =X15-Y15 -> 0 | AA15: 0 | AB15: 0 | AC15: 0 | AD15: =AB15-AC15 -> 0 | AE15: 0 | AF15: 3 | AG15: 3 | AH15: =AF15-AG15 -> 0 | AI15: 0 | AJ15: 2 | AK15: 2 | AL15: =AJ15-AK15 -> 0 | AM15: 0 | AN15: 0 | AO15: 0 | AP15: =AN15-AO15 -> 0 | AQ15: 0 | AR15: 0 | AS15: 0 | AT15: =AR15-AS15 -> 0 | AU15: 0 | AV15: 0 | AW15: 0 | AX15: =AV15-AW15 -> 0 | AY15: 0 | AZ15: 2 | BA15: 2 | BB15: =AZ15-BA15 -> 0 | BC15: 0 | BD15: 0 | BE15: 0 | BF15: =BD15-BE15 -> 0 | BG15: 0 | BH15: 0 | BI15: 0 | BJ15: =BH15-BI15 -> 0 | BK15: 0 | BL15: 0 | BM15: 0 | BN15: =BL15-BM15 -> 0 | BO15: 0 | BP15: 0 | BQ15: 0 | BR15: =BP15-BQ15 -> 0 | BS15: 0 | BT15: =SUM(E15,I15,M15,Q15,U15,Y15,AC15,AG15,AK15,AO15,AS15,AW15,BE15,BI15,BM15,BQ15,BA15) -> 13 | BU15: =SUM(BR15,BN15,BJ15,BF15,AX15,AT15,AP15,AL15,AH15,AD15,Z15,V15,R15,N15,J15,F15,BB15) -> 0 | BV15: =SUM(BS15,BO15,BK15,BG15,AY15,AU15,AQ15,AM15,AI15,AE15,AA15,W15,S15,O15,K15,G15, BC15) -> 0 | BW15: =BT15/(BT15+BU15) -> 1 | BX15: =BT15/(BT15+BV15) -> 1 | BY15: =2*(BX15*BW15)/(BX15+BW15) -> 1 | CC15: ex13 | CD15: =AVERAGE(BW27:BW28) -> 0.78571429 | CE15: =AVERAGE(BX27:BX28) -> 0.80833333 | CF15: =AVERAGE(BY27:BY28) -> 0.79442971
A16: python | C16: ex7_2 | D16: 3 | E16: 3 | F16: =D16-E16 -> 0 | G16: 0 | H16: 0 | I16: 0 | J16: =H16-I16 -> 0 | K16: 0 | L16: 0 | M16: 0 | N16: =L16-M16 -> 0 | O16: 0 | P16: 0 | Q16: 0 | R16: =P16-Q16 -> 0 | S16: 0 | T16: 0 | U16: 0 | V16: =T16-U16 -> 0 | W16: 0 | X16: 3 | Y16: 3 | Z16: 0 | AA16: 0 | AB16: 0 | AC16: 0 | AD16: =AB16-AC16 -> 0 | AE16: 0 | AF16: 3 | AG16: 3 | AH16: =AF16-AG16 -> 0 | AI16: 0 | AJ16: 2 | AK16: 2 | AL16: =AJ16-AK16 -> 0 | AM16: 0 | AN16: 0 | AO16: 0 | AP16: =AN16-AO16 -> 0 | AQ16: 0 | AR16: 0 | AS16: 0 | AT16: =AR16-AS16 -> 0 | AU16: 0 | AV16: 0 | AW16: 0 | AX16: =AV16-AW16 -> 0 | AY16: 0 | AZ16: 2 | BA16: 2 | BB16: =AZ16-BA16 -> 0 | BC16: 0 | BD16: 0 | BE16: 0 | BF16: =BD16-BE16 -> 0 | BG16: 0 | BH16: 0 | BI16: 0 | BJ16: =BH16-BI16 -> 0 | BK16: 0 | BL16: 0 | BM16: 0 | BN16: =BL16-BM16 -> 0 | BO16: 0 | BP16: 0 | BQ16: 0 | BR16: =BP16-BQ16 -> 0 | BS16: 0 | BT16: =SUM(E16,I16,M16,Q16,U16,Y16,AC16,AG16,AK16,AO16,AS16,AW16,BE16,BI16,BM16,BQ16,BA16) -> 13 | BU16: =SUM(BR16,BN16,BJ16,BF16,AX16,AT16,AP16,AL16,AH16,AD16,Z16,V16,R16,N16,J16,F16,BB16) -> 0 | BV16: =SUM(BS16,BO16,BK16,BG16,AY16,AU16,AQ16,AM16,AI16,AE16,AA16,W16,S16,O16,K16,G16, BC16) -> 0 | BW16: =BT16/(BT16+BU16) -> 1 | BX16: =BT16/(BT16+BV16) -> 1 | BY16: =2*(BX16*BW16)/(BX16+BW16) -> 1 | CC16: ex14 | CD16: =AVERAGE(BW29:BW30) -> 0.75 | CE16: =AVERAGE(BX29:BX30) -> 0.89181287 | CF16: =AVERAGE(BY29:BY30) -> 0.81463415
A17: python | C17: ex8_1 | D17: 2 | E17: 2 | F17: =D17-E17 -> 0 | G17: 0 | H17: 2 | I17: 1 | J17: =H17-I17 -> 1 | K17: 0 | L17: 1 | M17: 1 | N17: =L17-M17 -> 0 | O17: 0 | P17: 1 | Q17: 1 | R17: =P17-Q17 -> 0 | S17: 1 | T17: 1 | U17: 1 | V17: =T17-U17 -> 0 | W17: 0 | X17: 1 | Y17: 1 | Z17: =X17-Y17 -> 0 | AA17: 0 | AB17: 0 | AC17: 0 | AD17: =AB17-AC17 -> 0 | AE17: 0 | AF17: 1 | AG17: 1 | AH17: =AF17-AG17 -> 0 | AI17: 0 | AJ17: 0 | AK17: 0 | AL17: =AJ17-AK17 -> 0 | AM17: 0 | AN17: 0 | AO17: 0 | AP17: =AN17-AO17 -> 0 | AQ17: 0 | AR17: 0 | AS17: 0 | AT17: =AR17-AS17 -> 0 | AU17: 0 | AV17: 1 | AW17: 1 | AX17: =AV17-AW17 -> 0 | AY17: 0 | AZ17: 1 | BA17: 1 | BB17: =AZ17-BA17 -> 0 | BC17: 0 | BD17: 0 | BE17: 0 | BF17: =BD17-BE17 -> 0 | BG17: 0 | BH17: 0 | BI17: 0 | BJ17: =BH17-BI17 -> 0 | BK17: 0 | BL17: 0 | BM17: 0 | BN17: =BL17-BM17 -> 0 | BO17: 1 | BP17: 0 | BQ17: 0 | BR17: =BP17-BQ17 -> 0 | BS17: 0 | BT17: =SUM(E17,I17,M17,Q17,U17,Y17,AC17,AG17,AK17,AO17,AS17,AW17,BE17,BI17,BM17,BQ17,BA17) -> 10 | BU17: =SUM(BR17,BN17,BJ17,BF17,AX17,AT17,AP17,AL17,AH17,AD17,Z17,V17,R17,N17,J17,F17,BB17) -> 1 | BV17: =SUM(BS17,BO17,BK17,BG17,AY17,AU17,AQ17,AM17,AI17,AE17,AA17,W17,S17,O17,K17,G17, BC17) -> 2 | BW17: =BT17/(BT17+BU17) -> 0.90909091 | BX17: =BT17/(BT17+BV17) -> 0.83333333 | BY17: =2*(BX17*BW17)/(BX17+BW17) -> 0.86956522 | CC17: ex15 | CD17: =AVERAGE(BW31:BW32) -> 0.79166667 | CE17: =AVERAGE(BX31:BX32) -> 0.95 | CF17: =AVERAGE(BY31:BY32) -> 0.86363636
A18: python | C18: ex8_2 | D18: 2 | E18: 2 | F18: =D18-E18 -> 0 | G18: 0 | H18: 2 | I18: 1 | J18: =H18-I18 -> 1 | K18: 0 | L18: 1 | M18: 1 | N18: =L18-M18 -> 0 | O18: 0 | P18: 1 | Q18: 1 | R18: =P18-Q18 -> 0 | S18: 1 | T18: 1 | U18: 1 | V18: =T18-U18 -> 0 | W18: 0 | X18: 1 | Y18: 1 | Z18: =X18-Y18 -> 0 | AA18: 0 | AB18: 0 | AC18: 0 | AD18: =AB18-AC18 -> 0 | AE18: 0 | AF18: 1 | AG18: 1 | AH18: =AF18-AG18 -> 0 | AI18: 0 | AJ18: 0 | AK18: 0 | AL18: =AJ18-AK18 -> 0 | AM18: 0 | AN18: 0 | AO18: 0 | AP18: =AN18-AO18 -> 0 | AQ18: 0 | AR18: 0 | AS18: 0 | AT18: =AR18-AS18 -> 0 | AU18: 0 | AV18: 1 | AW18: 1 | AX18: =AV18-AW18 -> 0 | AY18: 0 | AZ18: 1 | BA18: 0 | BB18: =AZ18-BA18 -> 1 | BC18: 1 | BD18: 0 | BE18: 0 | BF18: =BD18-BE18 -> 0 | BG18: 0 | BH18: 0 | BI18: 0 | BJ18: =BH18-BI18 -> 0 | BK18: 0 | BL18: 0 | BM18: 0 | BN18: =BL18-BM18 -> 0 | BO18: 1 | BP18: 0 | BQ18: 0 | BR18: =BP18-BQ18 -> 0 | BS18: 0 | BT18: =SUM(E18,I18,M18,Q18,U18,Y18,AC18,AG18,AK18,AO18,AS18,AW18,BE18,BI18,BM18,BQ18,BA18) -> 9 | BU18: =SUM(BR18,BN18,BJ18,BF18,AX18,AT18,AP18,AL18,AH18,AD18,Z18,V18,R18,N18,J18,F18,BB18) -> 2 | BV18: =SUM(BS18,BO18,BK18,BG18,AY18,AU18,AQ18,AM18,AI18,AE18,AA18,W18,S18,O18,K18,G18, BC18) -> 3 | BW18: =BT18/(BT18+BU18) -> 0.81818182 | BX18: =BT18/(BT18+BV18) -> 0.75 | BY18: =2*(BX18*BW18)/(BX18+BW18) -> 0.7826087 | CC18: ex16 | CD18: =AVERAGE(BW33:BW34) -> 0.875 | CE18: =AVERAGE(BX33:BX34) -> 0.875 | CF18: =AVERAGE(BY33:BY34) -> 0.875
A19: python | C19: ex9_1 | D19: 2 | E19: 2 | F19: =D19-E19 -> 0 | G19: 0 | H19: 2 | I19: 0 | J19: =H19-I19 -> 2 | K19: 0 | L19: 1 | M19: 0 | N19: =L19-M19 -> 1 | O19: 0 | P19: 1 | Q19: 1 | R19: =P19-Q19 -> 0 | S19: 1 | T19: 1 | U19: 1 | V19: =T19-U19 -> 0 | W19: 0 | X19: 1 | Y19: 1 | Z19: =X19-Y19 -> 0 | AA19: 1 | AB19: 1 | AC19: 1 | AD19: =AB19-AC19 -> 0 | AE19: 1 | AF19: 1 | AG19: 1 | AH19: =AF19-AG19 -> 0 | AI19: 0 | AJ19: 0 | AK19: 0 | AL19: =AJ19-AK19 -> 0 | AM19: 0 | AN19: 0 | AO19: 0 | AP19: =AN19-AO19 -> 0 | AQ19: 0 | AR19: 0 | AS19: 0 | AT19: =AR19-AS19 -> 0 | AU19: 1 | AV19: 1 | AW19: 1 | AX19: =AV19-AW19 -> 0 | AY19: 0 | AZ19: 1 | BA19: 0 | BB19: =AZ19-BA19 -> 1 | BC19: 1 | BD19: 0 | BE19: 0 | BF19: =BD19-BE19 -> 0 | BG19: 0 | BH19: 0 | BI19: 0 | BJ19: =BH19-BI19 -> 0 | BK19: 0 | BL19: 0 | BM19: 0 | BN19: =BL19-BM19 -> 0 | BO19: 0 | BP19: 0 | BQ19: 0 | BR19: =BP19-BQ19 -> 0 | BS19: 0 | BT19: =SUM(E19,I19,M19,Q19,U19,Y19,AC19,AG19,AK19,AO19,AS19,AW19,BE19,BI19,BM19,BQ19,BA19) -> 8 | BU19: =SUM(BR19,BN19,BJ19,BF19,AX19,AT19,AP19,AL19,AH19,AD19,Z19,V19,R19,N19,J19,F19,BB19) -> 4 | BV19: =SUM(BS19,BO19,BK19,BG19,AY19,AU19,AQ19,AM19,AI19,AE19,AA19,W19,S19,O19,K19,G19, BC19) -> 5 | BW19: =BT19/(BT19+BU19) -> 0.66666667 | BX19: =BT19/(BT19+BV19) -> 0.61538462 | BY19: =2*(BX19*BW19)/(BX19+BW19) -> 0.64 | CC19: AVG | CD19: =AVERAGE(CD3:CD18) -> 0.79766331 | CE19: =AVERAGE(CE3:CE18) -> 0.84880213 | CF19: =AVERAGE(CF3:CF18) -> 0.81691116
A20: python | C20: ex9_2 | D20: 2 | E20: 2 | F20: =D20-E20 -> 0 | G20: 0 | H20: 2 | I20: 2 | J20: =H20-I20 -> 0 | K20: 0 | L20: 1 | M20: 1 | N20: =L20-M20 -> 0 | O20: 0 | P20: 1 | Q20: 1 | R20: =P20-Q20 -> 0 | S20: 1 | T20: 1 | U20: 1 | V20: =T20-U20 -> 0 | W20: 0 | X20: 1 | Y20: 1 | Z20: =X20-Y20 -> 0 | AA20: 0 | AB20: 1 | AC20: 1 | AD20: =AB20-AC20 -> 0 | AE20: 0 | AF20: 1 | AG20: 1 | AH20: =AF20-AG20 -> 0 | AI20: 0 | AJ20: 0 | AK20: 0 | AL20: =AJ20-AK20 -> 0 | AM20: 0 | AN20: 0 | AO20: 0 | AP20: =AN20-AO20 -> 0 | AQ20: 0 | AR20: 0 | AS20: 0 | AT20: =AR20-AS20 -> 0 | AU20: 1 | AV20: 1 | AW20: 1 | AX20: =AV20-AW20 -> 0 | AY20: 0 | AZ20: 1 | BA20: 0 | BB20: =AZ20-BA20 -> 1 | BC20: 1 | BD20: 0 | BE20: 0 | BF20: =BD20-BE20 -> 0 | BG20: 0 | BH20: 0 | BI20: 0 | BJ20: =BH20-BI20 -> 0 | BK20: 0 | BL20: 0 | BM20: 0 | BN20: =BL20-BM20 -> 0 | BO20: 0 | BP20: 0 | BQ20: 0 | BR20: =BP20-BQ20 -> 0 | BS20: 0 | BT20: =SUM(E20,I20,M20,Q20,U20,Y20,AC20,AG20,AK20,AO20,AS20,AW20,BE20,BI20,BM20,BQ20,BA20) -> 11 | BU20: =SUM(BR20,BN20,BJ20,BF20,AX20,AT20,AP20,AL20,AH20,AD20,Z20,V20,R20,N20,J20,F20,BB20) -> 1 | BV20: =SUM(BS20,BO20,BK20,BG20,AY20,AU20,AQ20,AM20,AI20,AE20,AA20,W20,S20,O20,K20,G20, BC20) -> 3 | BW20: =BT20/(BT20+BU20) -> 0.91666667 | BX20: =BT20/(BT20+BV20) -> 0.78571429 | BY20: =2*(BX20*BW20)/(BX20+BW20) -> 0.84615385
A21: python | C21: ex10_1 | D21: 2 | E21: 2 | F21: =D21-E21 -> 0 | G21: 0 | H21: 2 | I21: 0 | J21: =H21-I21 -> 2 | K21: 0 | L21: 3 | M21: 0 | N21: =L21-M21 -> 3 | O21: 0 | P21: 2 | Q21: 2 | R21: =P21-Q21 -> 0 | S21: 1 | T21: 2 | U21: 2 | V21: =T21-U21 -> 0 | W21: 0 | X21: 2 | Y21: 2 | Z21: =X21-Y21 -> 0 | AA21: 0 | AB21: 0 | AC21: 0 | AD21: =AB21-AC21 -> 0 | AE21: 0 | AF21: 2 | AG21: 2 | AH21: =AF21-AG21 -> 0 | AI21: 0 | AJ21: 0 | AK21: 0 | AL21: =AJ21-AK21 -> 0 | AM21: 0 | AN21: 0 | AO21: 0 | AP21: =AN21-AO21 -> 0 | AQ21: 0 | AR21: 0 | AS21: 0 | AT21: =AR21-AS21 -> 0 | AU21: 1 | AV21: 1 | AW21: 0 | AX21: =AV21-AW21 -> 1 | AY21: 0 | AZ21: 1 | BA21: 0 | BB21: =AZ21-BA21 -> 1 | BC21: 1 | BD21: 0 | BE21: 0 | BF21: =BD21-BE21 -> 0 | BG21: 0 | BH21: 0 | BI21: 0 | BJ21: =BH21-BI21 -> 0 | BK21: 0 | BL21: 0 | BM21: 0 | BN21: =BL21-BM21 -> 0 | BO21: 0 | BP21: 0 | BQ21: 0 | BR21: =BP21-BQ21 -> 0 | BS21: 0 | BT21: =SUM(E21,I21,M21,Q21,U21,Y21,AC21,AG21,AK21,AO21,AS21,AW21,BE21,BI21,BM21,BQ21,BA21) -> 10 | BU21: =SUM(BR21,BN21,BJ21,BF21,AX21,AT21,AP21,AL21,AH21,AD21,Z21,V21,R21,N21,J21,F21,BB21) -> 7 | BV21: =SUM(BS21,BO21,BK21,BG21,AY21,AU21,AQ21,AM21,AI21,AE21,AA21,W21,S21,O21,K21,G21, BC21) -> 3 | BW21: =BT21/(BT21+BU21) -> 0.58823529 | BX21: =BT21/(BT21+BV21) -> 0.76923077 | BY21: =2*(BX21*BW21)/(BX21+BW21) -> 0.66666667
A22: python | C22: ex10_2 | D22: 2 | E22: 2 | F22: =D22-E22 -> 0 | G22: 0 | H22: 2 | I22: 0 | J22: =H22-I22 -> 2 | K22: 0 | L22: 3 | M22: 0 | N22: =L22-M22 -> 3 | O22: 0 | P22: 2 | Q22: 2 | R22: =P22-Q22 -> 0 | S22: 1 | T22: 2 | U22: 2 | V22: =T22-U22 -> 0 | W22: 0 | X22: 2 | Y22: 2 | Z22: =X22-Y22 -> 0 | AA22: 0 | AB22: 0 | AC22: 0 | AD22: =AB22-AC22 -> 0 | AE22: 0 | AF22: 2 | AG22: 2 | AH22: =AF22-AG22 -> 0 | AI22: 0 | AJ22: 0 | AK22: 0 | AL22: =AJ22-AK22 -> 0 | AM22: 0 | AN22: 0 | AO22: 0 | AP22: =AN22-AO22 -> 0 | AQ22: 0 | AR22: 0 | AS22: 0 | AT22: =AR22-AS22 -> 0 | AU22: 1 | AV22: 1 | AW22: 0 | AX22: =AV22-AW22 -> 1 | AY22: 0 | AZ22: 1 | BA22: 0 | BB22: =AZ22-BA22 -> 1 | BC22: 1 | BD22: 0 | BE22: 0 | BF22: =BD22-BE22 -> 0 | BG22: 0 | BH22: 0 | BI22: 0 | BJ22: =BH22-BI22 -> 0 | BK22: 0 | BL22: 0 | BM22: 0 | BN22: =BL22-BM22 -> 0 | BO22: 0 | BP22: 0 | BQ22: 0 | BR22: =BP22-BQ22 -> 0 | BS22: 0 | BT22: =SUM(E22,I22,M22,Q22,U22,Y22,AC22,AG22,AK22,AO22,AS22,AW22,BE22,BI22,BM22,BQ22,BA22) -> 10 | BU22: =SUM(BR22,BN22,BJ22,BF22,AX22,AT22,AP22,AL22,AH22,AD22,Z22,V22,R22,N22,J22,F22,BB22) -> 7 | BV22: =SUM(BS22,BO22,BK22,BG22,AY22,AU22,AQ22,AM22,AI22,AE22,AA22,W22,S22,O22,K22,G22, BC22) -> 3 | BW22: =BT22/(BT22+BU22) -> 0.58823529 | BX22: =BT22/(BT22+BV22) -> 0.76923077 | BY22: =2*(BX22*BW22)/(BX22+BW22) -> 0.66666667
A23: python | C23: ex11_1 | D23: 2 | E23: 2 | F23: =D23-E23 -> 0 | G23: 0 | H23: 2 | I23: 1 | J23: =H23-I23 -> 1 | K23: 0 | L23: 0 | M23: 0 | N23: =L23-M23 -> 0 | O23: 0 | P23: 1 | Q23: 1 | R23: =P23-Q23 -> 0 | S23: 1 | T23: 1 | U23: 1 | V23: =T23-U23 -> 0 | W23: 0 | X23: 1 | Y23: 1 | Z23: =X23-Y23 -> 0 | AA23: 0 | AB23: 1 | AC23: 1 | AD23: =AB23-AC23 -> 0 | AE23: 0 | AF23: 1 | AG23: 1 | AH23: =AF23-AG23 -> 0 | AI23: 0 | AJ23: 0 | AK23: 0 | AL23: =AJ23-AK23 -> 0 | AM23: 0 | AN23: 0 | AO23: 0 | AP23: =AN23-AO23 -> 0 | AQ23: 0 | AR23: 1 | AS23: 0 | AT23: =AR23-AS23 -> 1 | AU23: 0 | AV23: 0 | AW23: 0 | AX23: =AV23-AW23 -> 0 | AY23: 1 | AZ23: 1 | BA23: 1 | BB23: =AZ23-BA23 -> 0 | BC23: 0 | BD23: 0 | BE23: 0 | BF23: =BD23-BE23 -> 0 | BG23: 0 | BH23: 0 | BI23: 0 | BJ23: =BH23-BI23 -> 0 | BK23: 0 | BL23: 0 | BM23: 0 | BN23: =BL23-BM23 -> 0 | BO23: 1 | BP23: 0 | BQ23: 0 | BR23: =BP23-BQ23 -> 0 | BS23: 0 | BT23: =SUM(E23,I23,M23,Q23,U23,Y23,AC23,AG23,AK23,AO23,AS23,AW23,BE23,BI23,BM23,BQ23,BA23) -> 9 | BU23: =SUM(BR23,BN23,BJ23,BF23,AX23,AT23,AP23,AL23,AH23,AD23,Z23,V23,R23,N23,J23,F23,BB23) -> 2 | BV23: =SUM(BS23,BO23,BK23,BG23,AY23,AU23,AQ23,AM23,AI23,AE23,AA23,W23,S23,O23,K23,G23, BC23) -> 3 | BW23: =BT23/(BT23+BU23) -> 0.81818182 | BX23: =BT23/(BT23+BV23) -> 0.75 | BY23: =2*(BX23*BW23)/(BX23+BW23) -> 0.7826087
A24: python | C24: ex11_2 | D24: 2 | E24: 2 | F24: =D24-E24 -> 0 | G24: 0 | H24: 2 | I24: 1 | J24: =H24-I24 -> 1 | K24: 0 | L24: 0 | M24: 0 | N24: =L24-M24 -> 0 | O24: 0 | P24: 1 | Q24: 1 | R24: =P24-Q24 -> 0 | S24: 1 | T24: 1 | U24: 1 | V24: =T24-U24 -> 0 | W24: 0 | X24: 1 | Y24: 1 | Z24: =X24-Y24 -> 0 | AA24: 0 | AB24: 1 | AC24: 1 | AD24: =AB24-AC24 -> 0 | AE24: 0 | AF24: 1 | AG24: 1 | AH24: =AF24-AG24 -> 0 | AI24: 0 | AJ24: 0 | AK24: 0 | AL24: =AJ24-AK24 -> 0 | AM24: 0 | AN24: 0 | AO24: 0 | AP24: =AN24-AO24 -> 0 | AQ24: 0 | AR24: 1 | AS24: 0 | AT24: =AR24-AS24 -> 1 | AU24: 0 | AV24: 0 | AW24: 0 | AX24: =AV24-AW24 -> 0 | AY24: 1 | AZ24: 1 | BA24: 1 | BB24: =AZ24-BA24 -> 0 | BC24: 0 | BD24: 0 | BE24: 0 | BF24: =BD24-BE24 -> 0 | BG24: 0 | BH24: 0 | BI24: 0 | BJ24: =BH24-BI24 -> 0 | BK24: 0 | BL24: 0 | BM24: 0 | BN24: =BL24-BM24 -> 0 | BO24: 1 | BP24: 0 | BQ24: 0 | BR24: =BP24-BQ24 -> 0 | BS24: 0 | BT24: =SUM(E24,I24,M24,Q24,U24,Y24,AC24,AG24,AK24,AO24,AS24,AW24,BE24,BI24,BM24,BQ24,BA24) -> 9 | BU24: =SUM(BR24,BN24,BJ24,BF24,AX24,AT24,AP24,AL24,AH24,AD24,Z24,V24,R24,N24,J24,F24,BB24) -> 2 | BV24: =SUM(BS24,BO24,BK24,BG24,AY24,AU24,AQ24,AM24,AI24,AE24,AA24,W24,S24,O24,K24,G24, BC24) -> 3 | BW24: =BT24/(BT24+BU24) -> 0.81818182 | BX24: =BT24/(BT24+BV24) -> 0.75 | BY24: =2*(BX24*BW24)/(BX24+BW24) -> 0.7826087
A25: python | C25: ex12_1 | D25: 2 | E25: 2 | F25: =D25-E25 -> 0 | G25: 0 | H25: 2 | I25: 0 | J25: =H25-I25 -> 2 | K25: 0 | L25: 0 | M25: 0 | N25: =L25-M25 -> 0 | O25: 0 | P25: 2 | Q25: 2 | R25: =P25-Q25 -> 0 | S25: 0 | T25: 2 | U25: 2 | V25: =T25-U25 -> 0 | W25: 0 | X25: 2 | Y25: 2 | Z25: =X25-Y25 -> 0 | AA25: 0 | AB25: 2 | AC25: 2 | AD25: =AB25-AC25 -> 0 | AE25: 0 | AF25: 2 | AG25: 2 | AH25: =AF25-AG25 -> 0 | AI25: 0 | AJ25: 0 | AK25: 0 | AL25: =AJ25-AK25 -> 0 | AM25: 0 | AN25: 0 | AO25: 0 | AP25: =AN25-AO25 -> 0 | AQ25: 0 | AR25: 1 | AS25: 0 | AT25: =AR25-AS25 -> 1 | AU25: 0 | AV25: 0 | AW25: 0 | AX25: =AV25-AW25 -> 0 | AY25: 1 | AZ25: 1 | BA25: 0 | BB25: =AZ25-BA25 -> 1 | BC25: 0 | BD25: 0 | BE25: 0 | BF25: =BD25-BE25 -> 0 | BG25: 0 | BH25: 0 | BI25: 0 | BJ25: =BH25-BI25 -> 0 | BK25: 0 | BL25: 0 | BM25: 0 | BN25: =BL25-BM25 -> 0 | BO25: 1 | BP25: 0 | BQ25: 0 | BR25: =BP25-BQ25 -> 0 | BS25: 0 | BT25: =SUM(E25,I25,M25,Q25,U25,Y25,AC25,AG25,AK25,AO25,AS25,AW25,BE25,BI25,BM25,BQ25,BA25) -> 12 | BU25: =SUM(BR25,BN25,BJ25,BF25,AX25,AT25,AP25,AL25,AH25,AD25,Z25,V25,R25,N25,J25,F25,BB25) -> 4 | BV25: =SUM(BS25,BO25,BK25,BG25,AY25,AU25,AQ25,AM25,AI25,AE25,AA25,W25,S25,O25,K25,G25, BC25) -> 2 | BW25: =BT25/(BT25+BU25) -> 0.75 | BX25: =BT25/(BT25+BV25) -> 0.85714286 | BY25: =2*(BX25*BW25)/(BX25+BW25) -> 0.8
A26: python | C26: ex12_2 | D26: 2 | E26: 2 | F26: =D26-E26 -> 0 | G26: 0 | H26: 2 | I26: 0 | J26: =H26-I26 -> 2 | K26: 0 | L26: 0 | M26: 0 | N26: =L26-M26 -> 0 | O26: 0 | P26: 2 | Q26: 2 | R26: =P26-Q26 -> 0 | S26: 0 | T26: 2 | U26: 2 | V26: =T26-U26 -> 0 | W26: 0 | X26: 2 | Y26: 2 | Z26: =X26-Y26 -> 0 | AA26: 0 | AB26: 2 | AC26: 2 | AD26: =AB26-AC26 -> 0 | AE26: 0 | AF26: 2 | AG26: 2 | AH26: =AF26-AG26 -> 0 | AI26: 0 | AJ26: 0 | AK26: 0 | AL26: =AJ26-AK26 -> 0 | AM26: 0 | AN26: 0 | AO26: 0 | AP26: =AN26-AO26 -> 0 | AQ26: 0 | AR26: 1 | AS26: 0 | AT26: =AR26-AS26 -> 1 | AU26: 0 | AV26: 0 | AW26: 0 | AX26: =AV26-AW26 -> 0 | AY26: 1 | AZ26: 1 | BA26: 0 | BB26: =AZ26-BA26 -> 1 | BC26: 0 | BD26: 0 | BE26: 0 | BF26: =BD26-BE26 -> 0 | BG26: 0 | BH26: 0 | BI26: 0 | BJ26: =BH26-BI26 -> 0 | BK26: 0 | BL26: 0 | BM26: 0 | BN26: =BL26-BM26 -> 0 | BO26: 1 | BP26: 0 | BQ26: 0 | BR26: =BP26-BQ26 -> 0 | BS26: 0 | BT26: =SUM(E26,I26,M26,Q26,U26,Y26,AC26,AG26,AK26,AO26,AS26,AW26,BE26,BI26,BM26,BQ26,BA26) -> 12 | BU26: =SUM(BR26,BN26,BJ26,BF26,AX26,AT26,AP26,AL26,AH26,AD26,Z26,V26,R26,N26,J26,F26,BB26) -> 4 | BV26: =SUM(BS26,BO26,BK26,BG26,AY26,AU26,AQ26,AM26,AI26,AE26,AA26,W26,S26,O26,K26,G26, BC26) -> 2 | BW26: =BT26/(BT26+BU26) -> 0.75 | BX26: =BT26/(BT26+BV26) -> 0.85714286 | BY26: =2*(BX26*BW26)/(BX26+BW26) -> 0.8
A27: python | C27: ex13_1 | D27: 2 | E27: 2 | F27: =D27-E27 -> 0 | G27: 0 | H27: 2 | I27: 2 | J27: =H27-I27 -> 0 | K27: 0 | L27: 2 | M27: 2 | N27: =L27-M27 -> 0 | O27: 0 | P27: 2 | Q27: 2 | R27: =P27-Q27 -> 0 | S27: 0 | T27: 2 | U27: 2 | V27: =T27-U27 -> 0 | W27: 0 | X27: 1 | Y27: 1 | Z27: =X27-Y27 -> 0 | AA27: 0 | AB27: 0 | AC27: 0 | AD27: =AB27-AC27 -> 0 | AE27: 0 | AF27: 1 | AG27: 1 | AH27: =AF27-AG27 -> 0 | AI27: 0 | AJ27: 0 | AK27: 0 | AL27: =AJ27-AK27 -> 0 | AM27: 0 | AN27: 0 | AO27: 0 | AP27: =AN27-AO27 -> 0 | AQ27: 0 | AR27: 0 | AS27: 0 | AT27: =AR27-AS27 -> 0 | AU27: 0 | AV27: 0 | AW27: 0 | AX27: =AV27-AW27 -> 0 | AY27: 1 | AZ27: 1 | BA27: 1 | BB27: =AZ27-BA27 -> 0 | BC27: 0 | BD27: 0 | BE27: 0 | BF27: =BD27-BE27 -> 0 | BG27: 0 | BH27: 0 | BI27: 0 | BJ27: =BH27-BI27 -> 0 | BK27: 0 | BL27: 0 | BM27: 0 | BN27: =BL27-BM27 -> 0 | BO27: 1 | BP27: 1 | BQ27: 0 | BR27: =BP27-BQ27 -> 1 | BS27: 0 | BT27: =SUM(E27,I27,M27,Q27,U27,Y27,AC27,AG27,AK27,AO27,AS27,AW27,BE27,BI27,BM27,BQ27,BA27) -> 13 | BU27: =SUM(BR27,BN27,BJ27,BF27,AX27,AT27,AP27,AL27,AH27,AD27,Z27,V27,R27,N27,J27,F27,BB27) -> 1 | BV27: =SUM(BS27,BO27,BK27,BG27,AY27,AU27,AQ27,AM27,AI27,AE27,AA27,W27,S27,O27,K27,G27, BC27) -> 2 | BW27: =BT27/(BT27+BU27) -> 0.92857143 | BX27: =BT27/(BT27+BV27) -> 0.86666667 | BY27: =2*(BX27*BW27)/(BX27+BW27) -> 0.89655172
A28: python | C28: ex13_2 | D28: 2 | E28: 2 | F28: =D28-E28 -> 0 | G28: 0 | H28: 2 | I28: 0 | J28: =H28-I28 -> 2 | K28: 0 | L28: 2 | M28: 0 | N28: =L28-M28 -> 2 | O28: 0 | P28: 2 | Q28: 2 | R28: =P28-Q28 -> 0 | S28: 0 | T28: 2 | U28: 2 | V28: =T28-U28 -> 0 | W28: 0 | X28: 1 | Y28: 1 | Z28: =X28-Y28 -> 0 | AA28: 1 | AB28: 0 | AC28: 0 | AD28: =AB28-AC28 -> 0 | AE28: 0 | AF28: 1 | AG28: 1 | AH28: =AF28-AG28 -> 0 | AI28: 0 | AJ28: 0 | AK28: 0 | AL28: =AJ28-AK28 -> 0 | AM28: 0 | AN28: 0 | AO28: 0 | AP28: =AN28-AO28 -> 0 | AQ28: 0 | AR28: 0 | AS28: 0 | AT28: =AR28-AS28 -> 0 | AU28: 0 | AV28: 0 | AW28: 0 | AX28: =AV28-AW28 -> 0 | AY28: 1 | AZ28: 1 | BA28: 1 | BB28: =AZ28-BA28 -> 0 | BC28: 0 | BD28: 0 | BE28: 0 | BF28: =BD28-BE28 -> 0 | BG28: 0 | BH28: 0 | BI28: 0 | BJ28: =BH28-BI28 -> 0 | BK28: 0 | BL28: 0 | BM28: 0 | BN28: =BL28-BM28 -> 0 | BO28: 1 | BP28: 1 | BQ28: 0 | BR28: =BP28-BQ28 -> 1 | BS28: 0 | BT28: =SUM(E28,I28,M28,Q28,U28,Y28,AC28,AG28,AK28,AO28,AS28,AW28,BE28,BI28,BM28,BQ28,BA28) -> 9 | BU28: =SUM(BR28,BN28,BJ28,BF28,AX28,AT28,AP28,AL28,AH28,AD28,Z28,V28,R28,N28,J28,F28,BB28) -> 5 | BV28: =SUM(BS28,BO28,BK28,BG28,AY28,AU28,AQ28,AM28,AI28,AE28,AA28,W28,S28,O28,K28,G28, BC28) -> 3 | BW28: =BT28/(BT28+BU28) -> 0.64285714 | BX28: =BT28/(BT28+BV28) -> 0.75 | BY28: =2*(BX28*BW28)/(BX28+BW28) -> 0.69230769
A29: python | C29: ex14_1 | D29: 2 | E29: 2 | F29: =D29-E29 -> 0 | G29: 0 | H29: 2 | I29: 0 | J29: =H29-I29 -> 2 | K29: 0 | L29: 2 | M29: 0 | N29: =L29-M29 -> 2 | O29: 0 | P29: 2 | Q29: 2 | R29: =P29-Q29 -> 0 | S29: 0 | T29: 2 | U29: 2 | V29: =T29-U29 -> 0 | W29: 0 | X29: 4 | Y29: 4 | Z29: =X29-Y29 -> 0 | AA29: 0 | AB29: 2 | AC29: 2 | AD29: =AB29-AC29 -> 0 | AE29: 0 | AF29: 4 | AG29: 4 | AH29: =AF29-AG29 -> 0 | AI29: 0 | AJ29: 0 | AK29: 0 | AL29: =AJ29-AK29 -> 0 | AM29: 0 | AN29: 0 | AO29: 0 | AP29: =AN29-AO29 -> 0 | AQ29: 0 | AR29: 0 | AS29: 0 | AT29: =AR29-AS29 -> 0 | AU29: 0 | AV29: 0 | AW29: 0 | AX29: =AV29-AW29 -> 0 | AY29: 1 | AZ29: 1 | BA29: 0 | BB29: =AZ29-BA29 -> 1 | BC29: 0 | BD29: 0 | BE29: 0 | BF29: =BD29-BE29 -> 0 | BG29: 0 | BH29: 0 | BI29: 0 | BJ29: =BH29-BI29 -> 0 | BK29: 0 | BL29: 0 | BM29: 0 | BN29: =BL29-BM29 -> 0 | BO29: 1 | BP29: 1 | BQ29: 0 | BR29: =BP29-BQ29 -> 1 | BS29: 0 | BT29: =SUM(E29,I29,M29,Q29,U29,Y29,AC29,AG29,AK29,AO29,AS29,AW29,BE29,BI29,BM29,BQ29,BA29) -> 16 | BU29: =SUM(BR29,BN29,BJ29,BF29,AX29,AT29,AP29,AL29,AH29,AD29,Z29,V29,R29,N29,J29,F29,BB29) -> 6 | BV29: =SUM(BS29,BO29,BK29,BG29,AY29,AU29,AQ29,AM29,AI29,AE29,AA29,W29,S29,O29,K29,G29, BC29) -> 2 | BW29: =BT29/(BT29+BU29) -> 0.72727273 | BX29: =BT29/(BT29+BV29) -> 0.88888889 | BY29: =2*(BX29*BW29)/(BX29+BW29) -> 0.8
A30: python | C30: ex14_2 | D30: 2 | E30: 2 | F30: =D30-E30 -> 0 | G30: 0 | H30: 2 | I30: 0 | J30: =H30-I30 -> 2 | K30: 0 | L30: 2 | M30: 0 | N30: =L30-M30 -> 2 | O30: 0 | P30: 2 | Q30: 2 | R30: =P30-Q30 -> 0 | S30: 0 | T30: 2 | U30: 2 | V30: =T30-U30 -> 0 | W30: 0 | X30: 4 | Y30: 4 | Z30: =X30-Y30 -> 0 | AA30: 0 | AB30: 2 | AC30: 2 | AD30: 0 | AE30: 0 | AF30: 4 | AG30: 4 | AH30: =AF30-AG30 -> 0 | AI30: 0 | AJ30: 0 | AK30: 0 | AL30: =AJ30-AK30 -> 0 | AM30: 0 | AN30: 0 | AO30: 0 | AP30: =AN30-AO30 -> 0 | AQ30: 1 | AR30: 0 | AS30: 0 | AT30: =AR30-AS30 -> 0 | AU30: 0 | AV30: 0 | AW30: 0 | AX30: =AV30-AW30 -> 0 | AY30: 0 | AZ30: 1 | BA30: 1 | BB30: =AZ30-BA30 -> 0 | BC30: 0 | BD30: 0 | BE30: 0 | BF30: =BD30-BE30 -> 0 | BG30: 0 | BH30: 0 | BI30: 0 | BJ30: =BH30-BI30 -> 0 | BK30: 0 | BL30: 0 | BM30: 0 | BN30: =BL30-BM30 -> 0 | BO30: 1 | BP30: 1 | BQ30: 0 | BR30: =BP30-BQ30 -> 1 | BS30: 0 | BT30: =SUM(E30,I30,M30,Q30,U30,Y30,AC30,AG30,AK30,AO30,AS30,AW30,BE30,BI30,BM30,BQ30,BA30) -> 17 | BU30: =SUM(BR30,BN30,BJ30,BF30,AX30,AT30,AP30,AL30,AH30,AD30,Z30,V30,R30,N30,J30,F30,BB30) -> 5 | BV30: =SUM(BS30,BO30,BK30,BG30,AY30,AU30,AQ30,AM30,AI30,AE30,AA30,W30,S30,O30,K30,G30, BC30) -> 2 | BW30: =BT30/(BT30+BU30) -> 0.77272727 | BX30: =BT30/(BT30+BV30) -> 0.89473684 | BY30: =2*(BX30*BW30)/(BX30+BW30) -> 0.82926829
A31: python | C31: ex15_1 | D31: 2 | E31: 2 | F31: =D31-E31 -> 0 | G31: 0 | H31: 1 | I31: 0 | J31: =H31-I31 -> 1 | K31: 0 | L31: 1 | M31: 0 | N31: =L31-M31 -> 1 | O31: 0 | P31: 1 | Q31: 1 | R31: =P31-Q31 -> 0 | S31: 0 | T31: 1 | U31: 1 | V31: =T31-U31 -> 0 | W31: 0 | X31: 2 | Y31: 2 | Z31: =X31-Y31 -> 0 | AA31: 0 | AB31: 0 | AC31: 0 | AD31: 0 | AE31: 0 | AF31: 2 | AG31: 2 | AH31: =AF31-AG31 -> 0 | AI31: 0 | AJ31: 0 | AK31: 0 | AL31: =AJ31-AK31 -> 0 | AM31: 0 | AN31: 0 | AO31: 0 | AP31: =AN31-AO31 -> 0 | AQ31: 1 | AR31: 0 | AS31: 0 | AT31: =AR31-AS31 -> 0 | AU31: 0 | AV31: 0 | AW31: 0 | AX31: =AV31-AW31 -> 0 | AY31: 0 | AZ31: 1 | BA31: 1 | BB31: =AZ31-BA31 -> 0 | BC31: 0 | BD31: 0 | BE31: 0 | BF31: =BD31-BE31 -> 0 | BG31: 0 | BH31: 0 | BI31: 0 | BJ31: =BH31-BI31 -> 0 | BK31: 0 | BL31: 0 | BM31: 0 | BN31: =BL31-BM31 -> 0 | BO31: 0 | BP31: 1 | BQ31: 0 | BR31: =BP31-BQ31 -> 1 | BS31: 0 | BT31: =SUM(E31,I31,M31,Q31,U31,Y31,AC31,AG31,AK31,AO31,AS31,AW31,BE31,BI31,BM31,BQ31,BA31) -> 9 | BU31: =SUM(BR31,BN31,BJ31,BF31,AX31,AT31,AP31,AL31,AH31,AD31,Z31,V31,R31,N31,J31,F31,BB31) -> 3 | BV31: =SUM(BS31,BO31,BK31,BG31,AY31,AU31,AQ31,AM31,AI31,AE31,AA31,W31,S31,O31,K31,G31, BC31) -> 1 | BW31: =BT31/(BT31+BU31) -> 0.75 | BX31: =BT31/(BT31+BV31) -> 0.9 | BY31: =2*(BX31*BW31)/(BX31+BW31) -> 0.81818182
A32: python | C32: ex15_2 | D32: 2 | E32: 2 | F32: =D32-E32 -> 0 | G32: 0 | H32: 1 | I32: 0 | J32: =H32-I32 -> 1 | K32: 0 | L32: 1 | M32: 0 | N32: =L32-M32 -> 1 | O32: 0 | P32: 1 | Q32: 1 | R32: =P32-Q32 -> 0 | S32: 0 | T32: 1 | U32: 1 | V32: =T32-U32 -> 0 | W32: 0 | X32: 2 | Y32: 2 | Z32: =X32-Y32 -> 0 | AA32: 0 | AB32: 0 | AC32: 0 | AD32: 0 | AE32: 0 | AF32: 2 | AG32: 2 | AH32: =AF32-AG32 -> 0 | AI32: 0 | AJ32: 0 | AK32: 0 | AL32: =AJ32-AK32 -> 0 | AM32: 0 | AN32: 0 | AO32: 0 | AP32: =AN32-AO32 -> 0 | AQ32: 0 | AR32: 0 | AS32: 0 | AT32: =AR32-AS32 -> 0 | AU32: 0 | AV32: 0 | AW32: 0 | AX32: =AV32-AW32 -> 0 | AY32: 0 | AZ32: 1 | BA32: 1 | BB32: =AZ32-BA32 -> 0 | BC32: 0 | BD32: 0 | BE32: 0 | BF32: =BD32-BE32 -> 0 | BG32: 0 | BH32: 0 | BI32: 0 | BJ32: =BH32-BI32 -> 0 | BK32: 0 | BL32: 0 | BM32: 0 | BN32: =BL32-BM32 -> 0 | BO32: 0 | BP32: 1 | BQ32: 1 | BR32: =BP32-BQ32 -> 0 | BS32: 0 | BT32: =SUM(E32,I32,M32,Q32,U32,Y32,AC32,AG32,AK32,AO32,AS32,AW32,BE32,BI32,BM32,BQ32,BA32) -> 10 | BU32: =SUM(BR32,BN32,BJ32,BF32,AX32,AT32,AP32,AL32,AH32,AD32,Z32,V32,R32,N32,J32,F32,BB32) -> 2 | BV32: =SUM(BS32,BO32,BK32,BG32,AY32,AU32,AQ32,AM32,AI32,AE32,AA32,W32,S32,O32,K32,G32, BC32) -> 0 | BW32: =BT32/(BT32+BU32) -> 0.83333333 | BX32: =BT32/(BT32+BV32) -> 1 | BY32: =2*(BX32*BW32)/(BX32+BW32) -> 0.90909091
A33: python | C33: ex16_1 | D33: 1 | E33: 1 | F33: =D33-E33 -> 0 | G33: 0 | H33: 1 | I33: 1 | J33: =H33-I33 -> 0 | K33: 0 | L33: 0 | M33: 0 | N33: =L33-M33 -> 0 | O33: 0 | P33: 5 | Q33: 5 | R33: =P33-Q33 -> 0 | S33: 0 | T33: 5 | U33: 3 | V33: =T33-U33 -> 2 | W33: 2 | X33: 0 | Y33: 0 | Z33: =X33-Y33 -> 0 | AA33: 0 | AB33: 0 | AC33: 0 | AD33: 0 | AE33: 0 | AF33: 0 | AG33: 0 | AH33: =AF33-AG33 -> 0 | AI33: 0 | AJ33: 0 | AK33: 0 | AL33: =AJ33-AK33 -> 0 | AM33: 0 | AN33: 0 | AO33: 0 | AP33: =AN33-AO33 -> 0 | AQ33: 0 | AR33: 0 | AS33: 0 | AT33: =AR33-AS33 -> 0 | AU33: 0 | AV33: 0 | AW33: 0 | AX33: =AV33-AW33 -> 0 | AY33: 0 | AZ33: 0 | BA33: 0 | BB33: =AZ33-BA33 -> 0 | BC33: 0 | BD33: 0 | BE33: 0 | BF33: =BD33-BE33 -> 0 | BG33: 0 | BH33: 0 | BI33: 0 | BJ33: =BH33-BI33 -> 0 | BK33: 0 | BL33: 0 | BM33: 0 | BN33: =BL33-BM33 -> 0 | BO33: 0 | BP33: 0 | BQ33: 0 | BR33: =BP33-BQ33 -> 0 | BS33: 0 | BT33: =SUM(E33,I33,M33,Q33,U33,Y33,AC33,AG33,AK33,AO33,AS33,AW33,BE33,BI33,BM33,BQ33,BA33) -> 10 | BU33: =SUM(BR33,BN33,BJ33,BF33,AX33,AT33,AP33,AL33,AH33,AD33,Z33,V33,R33,N33,J33,F33,BB33) -> 2 | BV33: =SUM(BS33,BO33,BK33,BG33,AY33,AU33,AQ33,AM33,AI33,AE33,AA33,W33,S33,O33,K33,G33, BC33) -> 2 | BW33: =BT33/(BT33+BU33) -> 0.83333333 | BX33: =BT33/(BT33+BV33) -> 0.83333333 | BY33: =2*(BX33*BW33)/(BX33+BW33) -> 0.83333333
A34: python | C34: ex16_2 | D34: 1 | E34: 1 | F34: =D34-E34 -> 0 | G34: 0 | H34: 1 | I34: 1 | J34: =H34-I34 -> 0 | K34: 0 | L34: 0 | M34: 0 | N34: =L34-M34 -> 0 | O34: 0 | P34: 5 | Q34: 5 | R34: =P34-Q34 -> 0 | S34: 0 | T34: 5 | U34: 4 | V34: =T34-U34 -> 1 | W34: 1 | X34: 0 | Y34: 0 | Z34: =X34-Y34 -> 0 | AA34: 0 | AB34: 0 | AC34: 0 | AD34: 0 | AE34: 0 | AF34: 0 | AG34: 0 | AH34: =AF34-AG34 -> 0 | AI34: 0 | AJ34: 0 | AK34: 0 | AL34: =AJ34-AK34 -> 0 | AM34: 0 | AN34: 0 | AO34: 0 | AP34: =AN34-AO34 -> 0 | AQ34: 0 | AR34: 0 | AS34: 0 | AT34: =AR34-AS34 -> 0 | AU34: 0 | AV34: 0 | AW34: 0 | AX34: =AV34-AW34 -> 0 | AY34: 0 | AZ34: 0 | BA34: 0 | BB34: =AZ34-BA34 -> 0 | BC34: 0 | BD34: 0 | BE34: 0 | BF34: =BD34-BE34 -> 0 | BG34: 0 | BH34: 0 | BI34: 0 | BJ34: =BH34-BI34 -> 0 | BK34: 0 | BL34: 0 | BM34: 0 | BN34: =BL34-BM34 -> 0 | BO34: 0 | BP34: 0 | BQ34: 0 | BR34: =BP34-BQ34 -> 0 | BS34: 0 | BT34: =SUM(E34,I34,M34,Q34,U34,Y34,AC34,AG34,AK34,AO34,AS34,AW34,BE34,BI34,BM34,BQ34,BA34) -> 11 | BU34: =SUM(BR34,BN34,BJ34,BF34,AX34,AT34,AP34,AL34,AH34,AD34,Z34,V34,R34,N34,J34,F34,BB34) -> 1 | BV34: =SUM(BS34,BO34,BK34,BG34,AY34,AU34,AQ34,AM34,AI34,AE34,AA34,W34,S34,O34,K34,G34, BC34) -> 1 | BW34: =BT34/(BT34+BU34) -> 0.91666667 | BX34: =BT34/(BT34+BV34) -> 0.91666667 | BY34: =2*(BX34*BW34)/(BX34+BW34) -> 0.91666667
C35: SUM | D35: =SUM(D3:D34) -> 68 | E35: =SUM(E3:E34) -> 68 | F35: =SUM(F3:F34) -> 0 | G35: =SUM(G3:G34) -> 0 | H35: =SUM(H3:H34) -> 46 | I35: =SUM(I3:I34) -> 14 | J35: =SUM(J3:J34) -> 32 | K35: =SUM(K3:K34) -> 0 | ... BS35: =SUM(BS3:BS34) -> 0
C37: Recall | D37: =IFERROR(E35/(E35+F35),"") -> 1 | H37: =IFERROR(I35/(I35+J35),"") -> 0.30434783 | L37: =IFERROR(M35/(M35+N35),"") -> 0.13157895 | P37: =IFERROR(Q35/(Q35+R35),"") -> 1 | T37: =IFERROR(U35/(U35+V35),"") -> 0.9375 | X37: =IFERROR(Y35/(Y35+Z35),"") -> 1 | AB37: =IFERROR(AC35/(AC35+AD35),"") -> 1 | AF37: =IFERROR(AG35/(AG35+AH35),"") -> 1 | AJ37: =IFERROR(AK35/(AK35+AL35),"") -> 0.8125 | AN37: =IFERROR(AO35/(AO35+AP35),"") -> 0 | AR37: =IFERROR(AS35/(AS35+AT35),"") -> 0 | AV37: =IFERROR(AW35/(AW35+AX35),"") -> 0.5 | AZ37: =IFERROR(BA35/(BA35+BB35),"") -> 0.58333333 | BD37: =IFERROR(BE35/(BE35+BF35),"") -> 0.25 | BH37: =IFERROR(BI35/(BI35+BJ35),"") -> 0.5 | BL37: =IFERROR(BM35/(BM35+BN35),"") | BP37: =IFERROR(BQ35/(BQ35+BR35),"") -> 0.16666667
C38: Precision | D38: =IFERROR(E35/(E35+G35),"") -> 1 | H38: =IFERROR(I35/(I35+K35),"") -> 1 | L38: =IFERROR(M35/(M35+O35),"") -> 1 | P38: =IFERROR(Q35/(Q35+S35),"") -> 0.75 | T38: =IFERROR(U35/(U35+W35),"") -> 0.9375 | X38: =IFERROR(Y35/(Y35+AA35),"") -> 0.93506494 | AB38: =IFERROR(AC35/(AC35+AE35),"") -> 0.95238095 | AF38: =IFERROR(AG35/(AG35+AI35),"") -> 1 | AJ38: =IFERROR(AK35/(AK35+AM35),"") -> 0.86666667 | AN38: =IFERROR(AO35/(AO35+AQ35),"") -> 0 | AR38: =IFERROR(AS35/(AS35+AU35),"") -> 0 | AV38: =IFERROR(AW35/(AW35+AY35),"") -> 0.28571429 | AZ38: =IFERROR(BA35/(BA35+BC35),"") -> 0.72413793 | BD38: =IFERROR(BE35/(BE35+BG35),"") -> 1 | BH38: =IFERROR(BI35/(BI35+BK35),"") -> 1 | BL38: =IFERROR(BM35/(BM35+BO35),"") -> 0 | BP38: =IFERROR(BQ35/(BQ35+BS35),"") -> 1
C39: F1 | D39: =IFERROR(2*D37*D38/(D37+D38),IF(AND(D37=0,D38=0),0,"")) -> 1 | H39: =IFERROR(2*H37*H38/(H37+H38),IF(AND(H37=0,H38=0),0,"")) -> 0.46666667 | L39: =IFERROR(2*L37*L38/(L37+L38),IF(AND(L37=0,L38=0),0,"")) -> 0.23255814 | P39: =IFERROR(2*P37*P38/(P37+P38),IF(AND(P37=0,P38=0),0,"")) -> 0.85714286 | T39: =IFERROR(2*T37*T38/(T37+T38),IF(AND(T37=0,T38=0),0,"")) -> 0.9375 | X39: =IFERROR(2*X37*X38/(X37+X38),IF(AND(X37=0,X38=0),0,"")) -> 0.96644295 | AB39: =IFERROR(2*AB37*AB38/(AB37+AB38),IF(AND(AB37=0,AB38=0),0,"")) -> 0.97560976 | AF39: =IFERROR(2*AF37*AF38/(AF37+AF38),IF(AND(AF37=0,AF38=0),0,"")) -> 1 | AJ39: =IFERROR(2*AJ37*AJ38/(AJ37+AJ38),IF(AND(AJ37=0,AJ38=0),0,"")) -> 0.83870968 | AN39: =IFERROR(2*AN37*AN38/(AN37+AN38),IF(AND(AN37=0,AN38=0),0,"")) -> 0 | AR39: =IFERROR(2*AR37*AR38/(AR37+AR38),IF(AND(AR37=0,AR38=0),0,"")) -> 0 | AV39: =IFERROR(2*AV37*AV38/(AV37+AV38),IF(AND(AV37=0,AV38=0),0,"")) -> 0.36363636 | AZ39: =IFERROR(2*AZ37*AZ38/(AZ37+AZ38),IF(AND(AZ37=0,AZ38=0),0,"")) -> 0.64615385 | BD39: =IFERROR(2*BD37*BD38/(BD37+BD38),IF(AND(BD37=0,BD38=0),0,"")) -> 0.4 | BH39: =IFERROR(2*BH37*BH38/(BH37+BH38),IF(AND(BH37=0,BH38=0),0,"")) -> 0.66666667 | BL39: =IFERROR(2*BL37*BL38/(BL37+BL38),IF(AND(BL37=0,BL38=0),0,"")) | BP39: =IFERROR(2*BP37*BP38/(BP37+BP38),IF(AND(BP37=0,BP38=0),0,"")) -> 0.28571429

Sheet baseline
A1: Language | B1: prompt | C1: Program Name | D1: C1 - Classes and Interfaces | H1: C2_Constructor | L1: C2a_Constructor_Parameters | P1: C3 - Attributes and Types | T1: C3a-Visibility attributes | X1: C4 - Methods | AB1: C4a-Parameters | AF1: C4b-Visibility methods_Constructors | AJ1: C5 - Inheritance Relationship | AN1: C6 - Realization Relationship | AR1: C7 - Association Relationship | AV1: C8 - Aggregation/Composition Relationship | AZ1: C9- Direction | BD1: C10 - Abstract Classes and Methods | BH1: C11 - Static Classes and Methods | BL1: C12 - Association Multiplicity | BP1: C13 - Dependency Relationship | BT1: TP | BU1: FN | BV1: FP | BW1: Recall | BX1: Precision | BY1: F1 | CC1: Program Name | CD1: =BW1 -> Recall | CE1: =BX1 -> Precision | CF1: =BY1 -> F1
D2: GT | E2: TP | F2: FN | G2: FP | H2: GT | I2: TP | J2: FN | K2: FP | L2: GT | M2: TP | N2: FN | O2: FP | P2: GT | Q2: TP | R2: FN | S2: FP | T2: GT | U2: TP | V2: FN | W2: FP | X2: GT | Y2: TP | Z2: FN | AA2: FP | AB2: GT | AC2: TP | AD2: FN | AE2: FP | AF2: GT | AG2: TP | AH2: FN | AI2: FP | AJ2: GT | AK2: TP | AL2: FN | AM2: FP | AN2: GT | AO2: TP | AP2: FN | AQ2: FP | AR2: GT | AS2: TP | AT2: FN | AU2: FP | AV2: GT | AW2: TP | AX2: FN | AY2: FP | AZ2: GT | BA2: TP | BB2: FN | BC2: FP | BD2: GT | BE2: TP | BF2: FN | BG2: FP | BH2: GT | BI2: TP | BJ2: FN | BK2: FP | BL2: GT | BM2: TP | BN2: FN | BO2: FP | BP2: GT | BQ2: TP | BR2: FN | BS2: FP
A3: python | B3: """<|User|> Generate a concise UML class diagram from the following python source code. Requirements: 1. Define each class and interface only once. 2. Include all attributes (with types) and methods. 3. Include all relationships: Inheritance, Realization, Dependency, Association, Composition, Aggregation. 4. Do not duplicate any class, method, attribute, or relationship. 5. Do not invent any element that does not exist in the given code. 6. Return ONLY a valid JSON object. Do not write any explanation, markdown, or extra text. python code: {code_content} <|Assistant|>""" | C3: ex1_1 | D3: 3 | E3: 3 | F3: =D3-E3 -> 0 | G3: 0 | H3: 3 | I3: 0 | J3: =H3-I3 -> 3 | K3: 0 | L3: 6 | M3: 0 | N3: =L3-M3 -> 6 | O3: 0 | P3: 4 | Q3: 4 | R3: =P3-Q3 -> 0 | S3: 0 | T3: 4 | U3: 4 | V3: =T3-U3 -> 0 | W3: 0 | X3: 3 | Y3: 3 | Z3: =X3-Y3 -> 0 | AA3: 0 | AB3: 0 | AC3: 0 | AD3: =AB3-AC3 -> 0 | AE3: 0 | AF3: 3 | AG3: 3 | AH3: =AF3-AG3 -> 0 | AI3: 0 | AJ3: 2 | AK3: 2 | AL3: =AJ3-AK3 -> 0 | AM3: 0 | AN3: 0 | AO3: 0 | AP3: =AN3-AO3 -> 0 | AQ3: 0 | AR3: 0 | AS3: 0 | AT3: =AR3-AS3 -> 0 | AU3: 0 | AV3: 0 | AW3: 0 | AX3: =AV3-AW3 -> 0 | AY3: 0 | AZ3: 2 | BA3: 2 | BB3: =AZ3-BA3 -> 0 | BC3: 0 | BD3: 0 | BE3: 0 | BF3: =BD3-BE3 -> 0 | BG3: 0 | BH3: 0 | BI3: 0 | BJ3: =BH3-BI3 -> 0 | BK3: 0 | BL3: 0 | BM3: 0 | BN3: =BL3-BM3 -> 0 | BO3: 0 | BP3: 0 | BQ3: 0 | BR3: =BP3-BQ3 -> 0 | BS3: 0 | BT3: =SUM(E3,I3,M3,Q3,U3,Y3,AC3,AG3,AK3,AO3,AS3,AW3,BE3,BI3,BM3,BQ3,BA3) -> 21 | BU3: =SUM(BR3,BN3,BJ3,BF3,AX3,AT3,AP3,AL3,AH3,AD3,Z3,V3,R3,N3,J3,F3,BB3) -> 9 | BV3: =SUM(BS3,BO3,BK3,BG3,AY3,AU3,AQ3,AM3,AI3,AE3,AA3,W3,S3,O3,K3,G3, BC3) -> 0 | BW3: =BT3/(BT3+BU3) -> 0.7 | BX3: =BT3/(BT3+BV3) -> 1 | BY3: =2*(BX3*BW3)/(BX3+BW3) -> 0.82352941 | CC3: ex1 | CD3: =AVERAGE(BW3:BW4) -> 0.7 | CE3: =AVERAGE(BX3:BX4) -> 1 | CF3: =AVERAGE(BY3:BY4) -> 0.82352941
A4: python | C4: ex1_2 | D4: 3 | E4: 3 | F4: =D4-E4 -> 0 | G4: 0 | H4: 3 | I4: 0 | J4: =H4-I4 -> 3 | K4: 0 | L4: 6 | M4: 0 | N4: =L4-M4 -> 6 | O4: 0 | P4: 4 | Q4: 4 | R4: =P4-Q4 -> 0 | S4: 0 | T4: 4 | U4: 4 | V4: =T4-U4 -> 0 | W4: 0 | X4: 3 | Y4: 3 | Z4: =X4-Y4 -> 0 | AA4: 0 | AB4: 0 | AC4: 0 | AD4: =AB4-AC4 -> 0 | AE4: 0 | AF4: 3 | AG4: 3 | AH4: =AF4-AG4 -> 0 | AI4: 0 | AJ4: 2 | AK4: 2 | AL4: =AJ4-AK4 -> 0 | AM4: 0 | AN4: 0 | AO4: 0 | AP4: =AN4-AO4 -> 0 | AQ4: 0 | AR4: 0 | AS4: 0 | AT4: =AR4-AS4 -> 0 | AU4: 0 | AV4: 0 | AW4: 0 | AX4: =AV4-AW4 -> 0 | AY4: 0 | AZ4: 2 | BA4: 2 | BB4: =AZ4-BA4 -> 0 | BC4: 0 | BD4: 0 | BE4: 0 | BF4: =BD4-BE4 -> 0 | BG4: 0 | BH4: 0 | BI4: 0 | BJ4: =BH4-BI4 -> 0 | BK4: 0 | BL4: 0 | BM4: 0 | BN4: =BL4-BM4 -> 0 | BO4: 0 | BP4: 0 | BQ4: 0 | BR4: =BP4-BQ4 -> 0 | BS4: 0 | BT4: =SUM(E4,I4,M4,Q4,U4,Y4,AC4,AG4,AK4,AO4,AS4,AW4,BE4,BI4,BM4,BQ4,BA4) -> 21 | BU4: =SUM(BR4,BN4,BJ4,BF4,AX4,AT4,AP4,AL4,AH4,AD4,Z4,V4,R4,N4,J4,F4,BB4) -> 9 | BV4: =SUM(BS4,BO4,BK4,BG4,AY4,AU4,AQ4,AM4,AI4,AE4,AA4,W4,S4,O4,K4,G4, BC4) -> 0 | BW4: =BT4/(BT4+BU4) -> 0.7 | BX4: =BT4/(BT4+BV4) -> 1 | BY4: =2*(BX4*BW4)/(BX4+BW4) -> 0.82352941 | CC4: ex2 | CD4: =AVERAGE(BW5:BW6) -> 0.8 | CE4: =AVERAGE(BX5:BX6) -> 0.64102564 | CF4: =AVERAGE(BY5:BY6) -> 0.71146245
A5: python | C5: ex2_1 | D5: 2 | E5: 2 | F5: =D5-E5 -> 0 | G5: 0 | H5: 2 | I5: 2 | J5: =H5-I5 -> 0 | K5: 0 | L5: 0 | M5: 0 | N5: =L5-M5 -> 0 | O5: 0 | P5: 0 | Q5: 0 | R5: =P5-Q5 -> 0 | S5: 2 | T5: 0 | U5: 0 | V5: =T5-U5 -> 0 | W5: 0 | X5: 2 | Y5: 2 | Z5: =X5-Y5 -> 0 | AA5: 0 | AB5: 0 | AC5: 0 | AD5: =AB5-AC5 -> 0 | AE5: 0 | AF5: 2 | AG5: 2 | AH5: =AF5-AG5 -> 0 | AI5: 0 | AJ5: 0 | AK5: 0 | AL5: =AJ5-AK5 -> 0 | AM5: 0 | AN5: 0 | AO5: 0 | AP5: =AN5-AO5 -> 0 | AQ5: 0 | AR5: 0 | AS5: 0 | AT5: =AR5-AS5 -> 0 | AU5: 0 | AV5: 1 | AW5: 0 | AX5: =AV5-AW5 -> 1 | AY5: 1 | AZ5: 1 | BA5: 0 | BB5: =AZ5-BA5 -> 1 | BC5: 1 | BD5: 0 | BE5: 0 | BF5: =BD5-BE5 -> 0 | BG5: 0 | BH5: 0 | BI5: 0 | BJ5: =BH5-BI5 -> 0 | BK5: 0 | BL5: 0 | BM5: 0 | BN5: =BL5-BM5 -> 0 | BO5: 1 | BP5: 0 | BQ5: 0 | BR5: =BP5-BQ5 -> 0 | BS5: 0 | BT5: =SUM(E5,I5,M5,Q5,U5,Y5,AC5,AG5,AK5,AO5,AS5,AW5,BE5,BI5,BM5,BQ5,BA5) -> 8 | BU5: =SUM(BR5,BN5,BJ5,BF5,AX5,AT5,AP5,AL5,AH5,AD5,Z5,V5,R5,N5,J5,F5,BB5) -> 2 | BV5: =SUM(BS5,BO5,BK5,BG5,AY5,AU5,AQ5,AM5,AI5,AE5,AA5,W5,S5,O5,K5,G5, BC5) -> 5 | BW5: =BT5/(BT5+BU5) -> 0.8 | BX5: =BT5/(BT5+BV5) -> 0.61538462 | BY5: =2*(BX5*BW5)/(BX5+BW5) -> 0.69565217 | CC5: ex3 | CD5: =AVERAGE(BW7:BW8) -> 0.6875 | CE5: =AVERAGE(BX7:BX8) -> 0.88141026 | CF5: =AVERAGE(BY7:BY8) -> 0.77216749
A6: python | C6: ex2_2 | D6: 2 | E6: 2 | F6: =D6-E6 -> 0 | G6: 0 | H6: 2 | I6: 2 | J6: =H6-I6 -> 0 | K6: 0 | L6: 0 | M6: 0 | N6: =L6-M6 -> 0 | O6: 0 | P6: 0 | Q6: 0 | R6: =P6-Q6 -> 0 | S6: 1 | T6: 0 | U6: 0 | V6: =T6-U6 -> 0 | W6: 0 | X6: 2 | Y6: 2 | Z6: =X6-Y6 -> 0 | AA6: 0 | AB6: 0 | AC6: 0 | AD6: =AB6-AC6 -> 0 | AE6: 0 | AF6: 2 | AG6: 2 | AH6: =AF6-AG6 -> 0 | AI6: 0 | AJ6: 0 | AK6: 0 | AL6: =AJ6-AK6 -> 0 | AM6: 0 | AN6: 0 | AO6: 0 | AP6: =AN6-AO6 -> 0 | AQ6: 0 | AR6: 0 | AS6: 0 | AT6: =AR6-AS6 -> 0 | AU6: 0 | AV6: 1 | AW6: 0 | AX6: =AV6-AW6 -> 1 | AY6: 1 | AZ6: 1 | BA6: 0 | BB6: =AZ6-BA6 -> 1 | BC6: 1 | BD6: 0 | BE6: 0 | BF6: =BD6-BE6 -> 0 | BG6: 0 | BH6: 0 | BI6: 0 | BJ6: =BH6-BI6 -> 0 | BK6: 0 | BL6: 0 | BM6: 0 | BN6: =BL6-BM6 -> 0 | BO6: 1 | BP6: 0 | BQ6: 0 | BR6: =BP6-BQ6 -> 0 | BS6: 0 | BT6: =SUM(E6,I6,M6,Q6,U6,Y6,AC6,AG6,AK6,AO6,AS6,AW6,BE6,BI6,BM6,BQ6,BA6) -> 8 | BU6: =SUM(BR6,BN6,BJ6,BF6,AX6,AT6,AP6,AL6,AH6,AD6,Z6,V6,R6,N6,J6,F6,BB6) -> 2 | BV6: =SUM(BS6,BO6,BK6,BG6,AY6,AU6,AQ6,AM6,AI6,AE6,AA6,W6,S6,O6,K6,G6, BC6) -> 4 | BW6: =BT6/(BT6+BU6) -> 0.8 | BX6: =BT6/(BT6+BV6) -> 0.66666667 | BY6: =2*(BX6*BW6)/(BX6+BW6) -> 0.72727273 | CC6: ex4 | CD6: =AVERAGE(BW9:BW10) -> 0.79166667 | CE6: =AVERAGE(BX9:BX10) -> 0.86752137 | CF6: =AVERAGE(BY9:BY10) -> 0.82095238
A7: python | C7: ex3_1 | D7: 2 | E7: 2 | F7: =D7-E7 -> 0 | G7: 0 | H7: 1 | I7: 0 | J7: =H7-I7 -> 1 | K7: 0 | L7: 1 | M7: 0 | N7: =L7-M7 -> 1 | O7: 0 | P7: 1 | Q7: 1 | R7: =P7-Q7 -> 0 | S7: 0 | T7: 1 | U7: 1 | V7: =T7-U7 -> 0 | W7: 0 | X7: 3 | Y7: 3 | Z7: =X7-Y7 -> 0 | AA7: 0 | AB7: 0 | AC7: 0 | AD7: =AB7-AC7 -> 0 | AE7: 0 | AF7: 3 | AG7: 3 | AH7: =AF7-AG7 -> 0 | AI7: 0 | AJ7: 0 | AK7: 0 | AL7: =AJ7-AK7 -> 0 | AM7: 1 | AN7: 1 | AO7: 0 | AP7: =AN7-AO7 -> 1 | AQ7: 0 | AR7: 0 | AS7: 0 | AT7: =AR7-AS7 -> 0 | AU7: 0 | AV7: 0 | AW7: 0 | AX7: =AV7-AW7 -> 0 | AY7: 0 | AZ7: 1 | BA7: 1 | BB7: =AZ7-BA7 -> 0 | BC7: 1 | BD7: 2 | BE7: 0 | BF7: =BD7-BE7 -> 2 | BG7: 0 | BH7: 0 | BI7: 0 | BJ7: =BH7-BI7 -> 0 | BK7: 0 | BL7: 0 | BM7: 0 | BN7: =BL7-BM7 -> 0 | BO7: 0 | BP7: 0 | BQ7: 0 | BR7: =BP7-BQ7 -> 0 | BS7: 0 | BT7: =SUM(E7,I7,M7,Q7,U7,Y7,AC7,AG7,AK7,AO7,AS7,AW7,BE7,BI7,BM7,BQ7,BA7) -> 11 | BU7: =SUM(BR7,BN7,BJ7,BF7,AX7,AT7,AP7,AL7,AH7,AD7,Z7,V7,R7,N7,J7,F7,BB7) -> 5 | BV7: =SUM(BS7,BO7,BK7,BG7,AY7,AU7,AQ7,AM7,AI7,AE7,AA7,W7,S7,O7,K7,G7, BC7) -> 2 | BW7: =BT7/(BT7+BU7) -> 0.6875 | BX7: =BT7/(BT7+BV7) -> 0.84615385 | BY7: =2*(BX7*BW7)/(BX7+BW7) -> 0.75862069 | CC7: ex5 | CD7: =AVERAGE(BW11:BW12) -> 0.92857143 | CE7: =AVERAGE(BX11:BX12) -> 0.95238095 | CF7: =AVERAGE(BY11:BY12) -> 0.94018583
A8: python | C8: ex3_2 | D8: 2 | E8: 2 | F8: =D8-E8 -> 0 | G8: 0 | H8: 1 | I8: 0 | J8: =H8-I8 -> 1 | K8: 0 | L8: 1 | M8: 0 | N8: =L8-M8 -> 1 | O8: 0 | P8: 1 | Q8: 1 | R8: =P8-Q8 -> 0 | S8: 0 | T8: 1 | U8: 1 | V8: =T8-U8 -> 0 | W8: 0 | X8: 3 | Y8: 3 | Z8: =X8-Y8 -> 0 | AA8: 0 | AB8: 0 | AC8: 0 | AD8: =AB8-AC8 -> 0 | AE8: 0 | AF8: 3 | AG8: 3 | AH8: =AF8-AG8 -> 0 | AI8: 0 | AJ8: 0 | AK8: 0 | AL8: =AJ8-AK8 -> 0 | AM8: 1 | AN8: 1 | AO8: 0 | AP8: =AN8-AO8 -> 1 | AQ8: 0 | AR8: 0 | AS8: 0 | AT8: =AR8-AS8 -> 0 | AU8: 0 | AV8: 0 | AW8: 0 | AX8: =AV8-AW8 -> 0 | AY8: 0 | AZ8: 1 | BA8: 1 | BB8: =AZ8-BA8 -> 0 | BC8: 0 | BD8: 2 | BE8: 0 | BF8: =BD8-BE8 -> 2 | BG8: 0 | BH8: 0 | BI8: 0 | BJ8: =BH8-BI8 -> 0 | BK8: 0 | BL8: 0 | BM8: 0 | BN8: =BL8-BM8 -> 0 | BO8: 0 | BP8: 0 | BQ8: 0 | BR8: =BP8-BQ8 -> 0 | BS8: 0 | BT8: =SUM(E8,I8,M8,Q8,U8,Y8,AC8,AG8,AK8,AO8,AS8,AW8,BE8,BI8,BM8,BQ8,BA8) -> 11 | BU8: =SUM(BR8,BN8,BJ8,BF8,AX8,AT8,AP8,AL8,AH8,AD8,Z8,V8,R8,N8,J8,F8,BB8) -> 5 | BV8: =SUM(BS8,BO8,BK8,BG8,AY8,AU8,AQ8,AM8,AI8,AE8,AA8,W8,S8,O8,K8,G8, BC8) -> 1 | BW8: =BT8/(BT8+BU8) -> 0.6875 | BX8: =BT8/(BT8+BV8) -> 0.91666667 | BY8: =2*(BX8*BW8)/(BX8+BW8) -> 0.78571429 | CC8: ex6 | CD8: =AVERAGE(BW13:BW14) -> 1 | CE8: =AVERAGE(BX13:BX14) -> 1 | CF8: =AVERAGE(BY13:BY14) -> 1
A9: python | C9: ex4_1 | D9: 1 | E9: 1 | F9: =D9-E9 -> 0 | G9: 0 | H9: 0 | I9: 0 | J9: =H9-I9 -> 0 | K9: 0 | L9: 0 | M9: 0 | N9: =L9-M9 -> 0 | O9: 0 | P9: 0 | Q9: 0 | R9: =P9-Q9 -> 0 | S9: 0 | T9: 0 | U9: 0 | V9: =T9-U9 -> 0 | W9: 0 | X9: 3 | Y9: 3 | Z9: =X9-Y9 -> 0 | AA9: 0 | AB9: 4 | AC9: 3 | AD9: =AB9-AC9 -> 1 | AE9: 0 | AF9: 3 | AG9: 3 | AH9: =AF9-AG9 -> 0 | AI9: 0 | AJ9: 0 | AK9: 0 | AL9: =AJ9-AK9 -> 0 | AM9: 0 | AN9: 0 | AO9: 0 | AP9: =AN9-AO9 -> 0 | AQ9: 0 | AR9: 0 | AS9: 0 | AT9: =AR9-AS9 -> 0 | AU9: 1 | AV9: 0 | AW9: 0 | AX9: =AV9-AW9 -> 0 | AY9: 0 | AZ9: 0 | BA9: 0 | BB9: =AZ9-BA9 -> 0 | BC9: 1 | BD9: 0 | BE9: 0 | BF9: =BD9-BE9 -> 0 | BG9: 0 | BH9: 1 | BI9: 1 | BJ9: =BH9-BI9 -> 0 | BK9: 0 | BL9: 0 | BM9: 0 | BN9: =BL9-BM9 -> 0 | BO9: 0 | BP9: 0 | BQ9: 0 | BR9: =BP9-BQ9 -> 0 | BS9: 0 | BT9: =SUM(E9,I9,M9,Q9,U9,Y9,AC9,AG9,AK9,AO9,AS9,AW9,BE9,BI9,BM9,BQ9,BA9) -> 11 | BU9: =SUM(BR9,BN9,BJ9,BF9,AX9,AT9,AP9,AL9,AH9,AD9,Z9,V9,R9,N9,J9,F9,BB9) -> 1 | BV9: =SUM(BS9,BO9,BK9,BG9,AY9,AU9,AQ9,AM9,AI9,AE9,AA9,W9,S9,O9,K9,G9, BC9) -> 2 | BW9: =BT9/(BT9+BU9) -> 0.91666667 | BX9: =BT9/(BT9+BV9) -> 0.84615385 | BY9: =2*(BX9*BW9)/(BX9+BW9) -> 0.88 | CC9: ex7 | CD9: =AVERAGE(BW15:BW16) -> 0.92307692 | CE9: =AVERAGE(BX15:BX16) -> 0.92307692 | CF9: =AVERAGE(BY15:BY16) -> 0.92307692
